Workbook

Sheet Monthly Data
A1: FaxScan24 Public Fax Activity, Group 225 (one row per branch per month, no duplicates)
A2: Source: FaxScan24 activity report emails in G:\Shared drives\Statistics\Faxing. Yellow rows are derived (see Note). Blue = figures copied from reports.
A4: Month | B4: Quarter | C4: Loc ID | D4: Branch | E4: Prepaid Fax Card Txns | F4: Credit/Debit Card Fax Txns | G4: Credit Card Sales | H4: Commission | I4: Source Type | J4: Source File | K4: Note
A5: 45748 | B5: Q2 2025 | C5: 1080 | D5: Fort Mill | E5: 0 | F5: 9 | G5: 38.2 | H5: 0 | I5: Quarterly report | J5: Quarterly Public Fax24 ... Fort Mill Branch QUARTYER 2.pdf
A6: 45748 | B6: Q2 2025 | C6: 1081 | D6: Lake Wylie | E6: 0 | F6: 3 | G6: 24.32 | H6: 0 | I6: Quarterly report | J6: Quarterly Public Fax24 ... Fort Mill Branch QUARTYER 2.pdf
A7: 45748 | B7: Q2 2025 | C7: 1082 | D7: Main | E7: 0 | F7: 30 | G7: 176.3 | H7: 17.76 | I7: Quarterly report | J7: Quarterly Public Fax24 ... Fort Mill Branch QUARTYER 2.pdf
A8: 45748 | B8: Q2 2025 | C8: 1084 | D8: York | E8: 0 | F8: 24 | G8: 177.73 | H8: 18.05 | I8: Quarterly report | J8: Quarterly Public Fax24 ... Fort Mill Branch QUARTYER 2.pdf
A9: 45748 | B9: Q2 2025 | C9: 1085 | D9: Clover | E9: 0 | F9: 11 | G9: 70.77 | H9: 1.04 | I9: Quarterly report | J9: Quarterly Public Fax24 ... Fort Mill Branch QUARTYER 2.pdf
A10: 45778 | B10: Q2 2025 | C10: 1080 | D10: Fort Mill | E10: 0 | F10: 3 | G10: 5.94 | H10: 0 | I10: Quarterly report | J10: Quarterly Public Fax24 ... Fort Mill Branch QUARTYER 2.pdf
A11: 45778 | B11: Q2 2025 | C11: 1081 | D11: Lake Wylie | E11: 0 | F11: 5 | G11: 19.82 | H11: 0 | I11: Quarterly report | J11: Quarterly Public Fax24 ... Fort Mill Branch QUARTYER 2.pdf
A12: 45778 | B12: Q2 2025 | C12: 1082 | D12: Main | E12: 0 | F12: 14 | G12: 71.09 | H12: 1.05 | I12: Quarterly report | J12: Quarterly Public Fax24 ... Fort Mill Branch QUARTYER 2.pdf
A13: 45778 | B13: Q2 2025 | C13: 1084 | D13: York | E13: 0 | F13: 16 | G13: 53.21 | H13: 0.16 | I13: Quarterly report | J13: Quarterly Public Fax24 ... Fort Mill Branch QUARTYER 2.pdf
A14: 45778 | B14: Q2 2025 | C14: 1085 | D14: Clover | E14: 0 | F14: 12 | G14: 44.45 | H14: 0 | I14: Quarterly report | J14: Quarterly Public Fax24 ... Fort Mill Branch QUARTYER 2.pdf
A15: 45809 | B15: Q2 2025 | C15: 1080 | D15: Fort Mill | E15: 0 | F15: 11 | G15: 57.39 | H15: 0.37 | I15: Quarterly report | J15: Quarterly Public Fax24 ... Fort Mill Branch QUARTYER 2.pdf
A16: 45809 | B16: Q2 2025 | C16: 1081 | D16: Lake Wylie | E16: 0 | F16: 11 | G16: 104.84 | H16: 3.47 | I16: Quarterly report | J16: Quarterly Public Fax24 ... Fort Mill Branch QUARTYER 2.pdf
... A19: 45809 | B19: Q2 2025 | C19: 1085 | D19: Clover | E19: 0 | F19: 14 | G19: 66.02 | H19: 0.8 | I19: Quarterly report | J19: Quarterly Public Fax24 ... Fort Mill Branch QUARTYER 2.pdf
A20: 45839 | B20: Q3 2025 | C20: 1080 | D20: Fort Mill | E20: 0 | F20: 7 | G20: 26.32 | H20: 0 | I20: Quarterly report | J20: Quarterly Public Fax24 ... Fort Mill Branch OCT.pdf | K20: Monthly email (file 'AUG') has identical figures; not counted again
A21: 45839 | B21: Q3 2025 | C21: 1081 | D21: Lake Wylie | E21: 0 | F21: 3 | G21: 14.32 | H21: 0 | I21: Quarterly report | J21: Quarterly Public Fax24 ... Fort Mill Branch OCT.pdf | K21: Monthly email (file 'AUG') has identical figures; not counted again
A22: 45839 | B22: Q3 2025 | C22: 1082 | D22: Main | E22: 0 | F22: 22 | G22: 91.85 | H22: 2.09 | I22: Quarterly report | J22: Quarterly Public Fax24 ... Fort Mill Branch OCT.pdf | K22: Monthly email (file 'AUG') has identical figures; not counted again
A23: 45839 | B23: Q3 2025 | C23: 1084 | D23: York | E23: 0 | F23: 15 | G23: 60.84 | H23: 0.54 | I23: Quarterly report | J23: Quarterly Public Fax24 ... Fort Mill Branch OCT.pdf | K23: Monthly email (file 'AUG') has identical figures; not counted again
A24: 45839 | B24: Q3 2025 | C24: 1085 | D24: Clover | E24: 0 | F24: 17 | G24: 92.65 | H24: 2.13 | I24: Quarterly report | J24: Quarterly Public Fax24 ... Fort Mill Branch OCT.pdf | K24: Monthly email (file 'AUG') has identical figures; not counted again
A25: 45870 | B25: Q3 2025 | C25: 1080 | D25: Fort Mill | E25: 0 | F25: 13 | G25: 51.96 | H25: 0.1 | I25: Quarterly report | J25: Quarterly Public Fax24 ... Fort Mill Branch OCT.pdf | K25: Monthly email (file '...Main Bran 2') has identical figures; not counted again
A26: 45870 | B26: Q3 2025 | C26: 1081 | D26: Lake Wylie | E26: 0 | F26: 3 | G26: 11.63 | H26: 0 | I26: Quarterly report | J26: Quarterly Public Fax24 ... Fort Mill Branch OCT.pdf | K26: Monthly email (file '...Main Bran 2') has identical figures; not counted again
A27: 45870 | B27: Q3 2025 | C27: 1082 | D27: Main | E27: 0 | F27: 19 | G27: 133.29 | H27: 9.16 | I27: Quarterly report | J27: Quarterly Public Fax24 ... Fort Mill Branch OCT.pdf | K27: Monthly email (file '...Main Bran 2') has identical figures; not counted again
A28: 45870 | B28: Q3 2025 | C28: 1084 | D28: York | E28: 0 | F28: 18 | G28: 138.47 | H28: 10.19 | I28: Quarterly report | J28: Quarterly Public Fax24 ... Fort Mill Branch OCT.pdf | K28: Monthly email (file '...Main Bran 2') has identical figures; not counted again
A29: 45870 | B29: Q3 2025 | C29: 1085 | D29: Clover | E29: 0 | F29: 11 | G29: 54.39 | H29: 0.22 | I29: Quarterly report | J29: Quarterly Public Fax24 ... Fort Mill Branch OCT.pdf | K29: Monthly email (file '...Main Bran 2') has identical figures; not counted again
A30: 45901 | B30: Q3 2025 | C30: 1080 | D30: Fort Mill | E30: 0 | F30: 10 | G30: 39.71 | H30: 0 | I30: Quarterly report | J30: Quarterly Public Fax24 ... Fort Mill Branch OCT.pdf
A31: 45901 | B31: Q3 2025 | C31: 1081 | D31: Lake Wylie | E31: 0 | F31: 2 | G31: 5.19 | H31: 0 | I31: Quarterly report | J31: Quarterly Public Fax24 ... Fort Mill Branch OCT.pdf
A32: 45901 | B32: Q3 2025 | C32: 1082 | D32: Main | E32: 0 | F32: 18 | G32: 110.47 | H32: 4.59 | I32: Quarterly report | J32: Quarterly Public Fax24 ... Fort Mill Branch OCT.pdf
A33: 45901 | B33: Q3 2025 | C33: 1084 | D33: York | E33: 0 | F33: 14 | G33: 52.47 | H33: 0.12 | I33: Quarterly report | J33: Quarterly Public Fax24 ... Fort Mill Branch OCT.pdf
A34: 45901 | B34: Q3 2025 | C34: 1085 | D34: Clover | E34: 0 | F34: 20 | G34: 97.59 | H34: 2.38 | I34: Quarterly report | J34: Quarterly Public Fax24 ... Fort Mill Branch OCT.pdf
A35: 45931 | B35: Q4 2025 | C35: 1080 | D35: Fort Mill | E35: 0 | F35: 13 | G35: 83.65 | H35: 1.68 | I35: Quarterly report | J35: Quarterly Public Fax24 ... Fort Mill Branch.pdf | K35: Monthly email (file 'NOV') has identical figures; not counted again
A36: 45931 | B36: Q4 2025 | C36: 1081 | D36: Lake Wylie | E36: 0 | F36: 3 | G36: 17.63 | H36: 0 | I36: Quarterly report | J36: Quarterly Public Fax24 ... Fort Mill Branch.pdf | K36: Monthly email (file 'NOV') has identical figures; not counted again
A37: 45931 | B37: Q4 2025 | C37: 1082 | D37: Main | E37: 0 | F37: 0 | G37: 0 | H37: 0 | I37: Quarterly report | J37: Quarterly Public Fax24 ... Fort Mill Branch.pdf | K37: Monthly email (file 'NOV') has identical figures; not counted again
A38: 45931 | B38: Q4 2025 | C38: 1084 | D38: York | E38: 0 | F38: 23 | G38: 87.98 | H38: 1.9 | I38: Quarterly report | J38: Quarterly Public Fax24 ... Fort Mill Branch.pdf | K38: Monthly email (file 'NOV') has identical figures; not counted again
A39: 45931 | B39: Q4 2025 | C39: 1085 | D39: Clover | E39: 0 | F39: 7 | G39: 30.08 | H39: 0 | I39: Quarterly report | J39: Quarterly Public Fax24 ... Fort Mill Branch.pdf | K39: Monthly email (file 'NOV') has identical figures; not counted again
A40: 45962 | B40: Q4 2025 | C40: 1080 | D40: Fort Mill | E40: 0 | F40: 5 | G40: 24.51 | H40: 0 | I40: Quarterly report | J40: Quarterly Public Fax24 ... Fort Mill Branch.pdf | K40: Monthly email (file '...Main Bran.pdf') has identical figures; not counted again
A41: 45962 | B41: Q4 2025 | C41: 1081 | D41: Lake Wylie | E41: 0 | F41: 1 | G41: 2.44 | H41: 0 | I41: Quarterly report | J41: Quarterly Public Fax24 ... Fort Mill Branch.pdf | K41: Monthly email (file '...Main Bran.pdf') has identical figures; not counted again
A42: 45962 | B42: Q4 2025 | C42: 1082 | D42: Main | E42: 0 | F42: 0 | G42: 0 | H42: 0 | I42: Quarterly report | J42: Quarterly Public Fax24 ... Fort Mill Branch.pdf | K42: Monthly email (file '...Main Bran.pdf') has identical figures; not counted again
A43: 45962 | B43: Q4 2025 | C43: 1084 | D43: York | E43: 0 | F43: 18 | G43: 95.09 | H43: 2.25 | I43: Quarterly report | J43: Quarterly Public Fax24 ... Fort Mill Branch.pdf | K43: Monthly email (file '...Main Bran.pdf') has identical figures; not counted again
...

Sheet Quarterly Summary
A1: Quarterly totals (built from Monthly Data) checked against FaxScan24 quarterly reports
A3: Quarter | B3: Fax Txns | C3: Credit Card Sales | D3: Commission | E3: Reported Fax Txns | F3: Reported Sales | G3: Reported Commission | H3: Fax Diff | I3: Sales Diff | J3: Commission Diff | K3: Quarterly Report
A4: Q2 2025 | B4: =SUMIFS('Monthly Data'!$F$5:$F$94,'Monthly Data'!$B$5:$B$94,$A4) -> 200 | C4: =SUMIFS('Monthly Data'!$G$5:$G$94,'Monthly Data'!$B$5:$B$94,$A4) -> 1117.84 | D4: =SUMIFS('Monthly Data'!$H$5:$H$94,'Monthly Data'!$B$5:$B$94,$A4) -> 52.68 | E4: 200 | F4: 1117.84 | G4: 52.68 | H4: =IF(ISNUMBER(E4),B4-E4,"n/a") -> 0 | I4: =IF(ISNUMBER(F4),C4-F4,"n/a") -> 0 | J4: =IF(ISNUMBER(G4),D4-G4,"n/a") -> 0 | K4: Quarterly Public Fax24 ... Fort Mill Branch QUARTYER 2.pdf
A5: Q3 2025 | B5: =SUMIFS('Monthly Data'!$F$5:$F$94,'Monthly Data'!$B$5:$B$94,$A5) -> 192 | C5: =SUMIFS('Monthly Data'!$G$5:$G$94,'Monthly Data'!$B$5:$B$94,$A5) -> 981.15 | D5: =SUMIFS('Monthly Data'!$H$5:$H$94,'Monthly Data'!$B$5:$B$94,$A5) -> 31.52 | E5: 192 | F5: 981.15 | G5: 31.53 | H5: =IF(ISNUMBER(E5),B5-E5,"n/a") -> 0 | I5: =IF(ISNUMBER(F5),C5-F5,"n/a") -> 0 | J5: =IF(ISNUMBER(G5),D5-G5,"n/a") -> -0.01 | K5: Quarterly Public Fax24 ... Fort Mill Branch OCT.pdf
A6: Q4 2025 | B6: =SUMIFS('Monthly Data'!$F$5:$F$94,'Monthly Data'!$B$5:$B$94,$A6) -> 126 | C6: =SUMIFS('Monthly Data'!$G$5:$G$94,'Monthly Data'!$B$5:$B$94,$A6) -> 669.12 | D6: =SUMIFS('Monthly Data'!$H$5:$H$94,'Monthly Data'!$B$5:$B$94,$A6) -> 11.81 | E6: 126 | F6: 669.12 | G6: 11.82 | H6: =IF(ISNUMBER(E6),B6-E6,"n/a") -> 0 | I6: =IF(ISNUMBER(F6),C6-F6,"n/a") -> 0 | J6: =IF(ISNUMBER(G6),D6-G6,"n/a") -> -0.01 | K6: Quarterly Public Fax24 ... Fort Mill Branch.pdf
A7: Q1 2026 | B7: =SUMIFS('Monthly Data'!$F$5:$F$94,'Monthly Data'!$B$5:$B$94,$A7) -> 102 | C7: =SUMIFS('Monthly Data'!$G$5:$G$94,'Monthly Data'!$B$5:$B$94,$A7) -> 560.19 | D7: =SUMIFS('Monthly Data'!$H$5:$H$94,'Monthly Data'!$B$5:$B$94,$A7) -> 13.88 | E7: n/a | F7: n/a | G7: n/a | H7: =IF(ISNUMBER(E7),B7-E7,"n/a") -> n/a | I7: =IF(ISNUMBER(F7),C7-F7,"n/a") -> n/a | J7: =IF(ISNUMBER(G7),D7-G7,"n/a") -> n/a | K7: None received (Jan–Mar monthly reports only)
A8: Q2 2026 | B8: =SUMIFS('Monthly Data'!$F$5:$F$94,'Monthly Data'!$B$5:$B$94,$A8) -> 174 | C8: =SUMIFS('Monthly Data'!$G$5:$G$94,'Monthly Data'!$B$5:$B$94,$A8) -> 1034.13 | D8: =SUMIFS('Monthly Data'!$H$5:$H$94,'Monthly Data'!$B$5:$B$94,$A8) -> 46.08 | E8: 174 | F8: 1034.13 | G8: 46.08 | H8: =IF(ISNUMBER(E8),B8-E8,"n/a") -> 0 | I8: =IF(ISNUMBER(F8),C8-F8,"n/a") -> 0 | J8: =IF(ISNUMBER(G8),D8-G8,"n/a") -> 0 | K8: FaxScan24 Activity Report — 04_01_2026 to 06_30_2026.pdf
A9: Q3 2026 | B9: =SUMIFS('Monthly Data'!$F$5:$F$94,'Monthly Data'!$B$5:$B$94,$A9) -> 203 | C9: =SUMIFS('Monthly Data'!$G$5:$G$94,'Monthly Data'!$B$5:$B$94,$A9) -> 1070.85 | D9: =SUMIFS('Monthly Data'!$H$5:$H$94,'Monthly Data'!$B$5:$B$94,$A9) -> 45.95 | E9: 203 | F9: 1070.85 | G9: 45.95 | H9: =IF(ISNUMBER(E9),B9-E9,"n/a") -> 0 | I9: =IF(ISNUMBER(F9),C9-F9,"n/a") -> 0 | J9: =IF(ISNUMBER(G9),D9-G9,"n/a") -> 0 | K9: FaxScan24 Activity Report — 07_01_2026 to 09_30_2026.pdf (duplicate of Jul–Sep monthly; check only)
A10: Total | B10: =SUM(B4:B9) -> 997 | C10: =SUM(C4:C9) -> 5433.28 | D10: =SUM(D4:D9) -> 201.92
A12: Diff columns should be zero. Q3 and Q4 2025 commissions are off by $0.01 because the vendor's own quarterly totals round differently from its monthly rows (e.g. York Q3 2025 months add to $10.85 but the report shows $10.86). Q2 2026 matches by construction because June was derived from that report.

Sheet By Branch
A1: Fax transactions by branch and month
A3: Fax transactions
A4: Month | B4: Fort Mill | C4: Lake Wylie | D4: Main | E4: York | F4: Clover | G4: Total
A5: 45748 | B5: =SUMIFS('Monthly Data'!$F$5:$F$94,'Monthly Data'!$A$5:$A$94,$A5,'Monthly Data'!$C$5:$C$94,1080) -> 9 | C5: =SUMIFS('Monthly Data'!$F$5:$F$94,'Monthly Data'!$A$5:$A$94,$A5,'Monthly Data'!$C$5:$C$94,1081) -> 3 | D5: =SUMIFS('Monthly Data'!$F$5:$F$94,'Monthly Data'!$A$5:$A$94,$A5,'Monthly Data'!$C$5:$C$94,1082) -> 30 | E5: =SUMIFS('Monthly Data'!$F$5:$F$94,'Monthly Data'!$A$5:$A$94,$A5,'Monthly Data'!$C$5:$C$94,1084) -> 24 | F5: =SUMIFS('Monthly Data'!$F$5:$F$94,'Monthly Data'!$A$5:$A$94,$A5,'Monthly Data'!$C$5:$C$94,1085) -> 11 | G5: =SUM(B5:F5) -> 77
A6: 45778 | B6: =SUMIFS('Monthly Data'!$F$5:$F$94,'Monthly Data'!$A$5:$A$94,$A6,'Monthly Data'!$C$5:$C$94,1080) -> 3 | C6: =SUMIFS('Monthly Data'!$F$5:$F$94,'Monthly Data'!$A$5:$A$94,$A6,'Monthly Data'!$C$5:$C$94,1081) -> 5 | D6: =SUMIFS('Monthly Data'!$F$5:$F$94,'Monthly Data'!$A$5:$A$94,$A6,'Monthly Data'!$C$5:$C$94,1082) -> 14 | E6: =SUMIFS('Monthly Data'!$F$5:$F$94,'Monthly Data'!$A$5:$A$94,$A6,'Monthly Data'!$C$5:$C$94,1084) -> 16 | F6: =SUMIFS('Monthly Data'!$F$5:$F$94,'Monthly Data'!$A$5:$A$94,$A6,'Monthly Data'!$C$5:$C$94,1085) -> 12 | G6: =SUM(B6:F6) -> 50
A7: 45809 | B7: =SUMIFS('Monthly Data'!$F$5:$F$94,'Monthly Data'!$A$5:$A$94,$A7,'Monthly Data'!$C$5:$C$94,1080) -> 11 | C7: =SUMIFS('Monthly Data'!$F$5:$F$94,'Monthly Data'!$A$5:$A$94,$A7,'Monthly Data'!$C$5:$C$94,1081) -> 11 | D7: =SUMIFS('Monthly Data'!$F$5:$F$94,'Monthly Data'!$A$5:$A$94,$A7,'Monthly Data'!$C$5:$C$94,1082) -> 18 | E7: =SUMIFS('Monthly Data'!$F$5:$F$94,'Monthly Data'!$A$5:$A$94,$A7,'Monthly Data'!$C$5:$C$94,1084) -> 19 | F7: =SUMIFS('Monthly Data'!$F$5:$F$94,'Monthly Data'!$A$5:$A$94,$A7,'Monthly Data'!$C$5:$C$94,1085) -> 14 | G7: =SUM(B7:F7) -> 73
A8: 45839 | B8: =SUMIFS('Monthly Data'!$F$5:$F$94,'Monthly Data'!$A$5:$A$94,$A8,'Monthly Data'!$C$5:$C$94,1080) -> 7 | C8: =SUMIFS('Monthly Data'!$F$5:$F$94,'Monthly Data'!$A$5:$A$94,$A8,'Monthly Data'!$C$5:$C$94,1081) -> 3 | D8: =SUMIFS('Monthly Data'!$F$5:$F$94,'Monthly Data'!$A$5:$A$94,$A8,'Monthly Data'!$C$5:$C$94,1082) -> 22 | E8: =SUMIFS('Monthly Data'!$F$5:$F$94,'Monthly Data'!$A$5:$A$94,$A8,'Monthly Data'!$C$5:$C$94,1084) -> 15 | F8: =SUMIFS('Monthly Data'!$F$5:$F$94,'Monthly Data'!$A$5:$A$94,$A8,'Monthly Data'!$C$5:$C$94,1085) -> 17 | G8: =SUM(B8:F8) -> 64
A9: 45870 | B9: =SUMIFS('Monthly Data'!$F$5:$F$94,'Monthly Data'!$A$5:$A$94,$A9,'Monthly Data'!$C$5:$C$94,1080) -> 13 | C9: =SUMIFS('Monthly Data'!$F$5:$F$94,'Monthly Data'!$A$5:$A$94,$A9,'Monthly Data'!$C$5:$C$94,1081) -> 3 | D9: =SUMIFS('Monthly Data'!$F$5:$F$94,'Monthly Data'!$A$5:$A$94,$A9,'Monthly Data'!$C$5:$C$94,1082) -> 19 | E9: =SUMIFS('Monthly Data'!$F$5:$F$94,'Monthly Data'!$A$5:$A$94,$A9,'Monthly Data'!$C$5:$C$94,1084) -> 18 | F9: =SUMIFS('Monthly Data'!$F$5:$F$94,'Monthly Data'!$A$5:$A$94,$A9,'Monthly Data'!$C$5:$C$94,1085) -> 11 | G9: =SUM(B9:F9) -> 64
A10: 45901 | B10: =SUMIFS('Monthly Data'!$F$5:$F$94,'Monthly Data'!$A$5:$A$94,$A10,'Monthly Data'!$C$5:$C$94,1080) -> 10 | C10: =SUMIFS('Monthly Data'!$F$5:$F$94,'Monthly Data'!$A$5:$A$94,$A10,'Monthly Data'!$C$5:$C$94,1081) -> 2 | D10: =SUMIFS('Monthly Data'!$F$5:$F$94,'Monthly Data'!$A$5:$A$94,$A10,'Monthly Data'!$C$5:$C$94,1082) -> 18 | E10: =SUMIFS('Monthly Data'!$F$5:$F$94,'Monthly Data'!$A$5:$A$94,$A10,'Monthly Data'!$C$5:$C$94,1084) -> 14 | F10: =SUMIFS('Monthly Data'!$F$5:$F$94,'Monthly Data'!$A$5:$A$94,$A10,'Monthly Data'!$C$5:$C$94,1085) -> 20 | G10: =SUM(B10:F10) -> 64
A11: 45931 | B11: =SUMIFS('Monthly Data'!$F$5:$F$94,'Monthly Data'!$A$5:$A$94,$A11,'Monthly Data'!$C$5:$C$94,1080) -> 13 | C11: =SUMIFS('Monthly Data'!$F$5:$F$94,'Monthly Data'!$A$5:$A$94,$A11,'Monthly Data'!$C$5:$C$94,1081) -> 3 | D11: =SUMIFS('Monthly Data'!$F$5:$F$94,'Monthly Data'!$A$5:$A$94,$A11,'Monthly Data'!$C$5:$C$94,1082) -> 0 | E11: =SUMIFS('Monthly Data'!$F$5:$F$94,'Monthly Data'!$A$5:$A$94,$A11,'Monthly Data'!$C$5:$C$94,1084) -> 23 | F11: =SUMIFS('Monthly Data'!$F$5:$F$94,'Monthly Data'!$A$5:$A$94,$A11,'Monthly Data'!$C$5:$C$94,1085) -> 7 | G11: =SUM(B11:F11) -> 46
A12: 45962 | B12: =SUMIFS('Monthly Data'!$F$5:$F$94,'Monthly Data'!$A$5:$A$94,$A12,'Monthly Data'!$C$5:$C$94,1080) -> 5 | C12: =SUMIFS('Monthly Data'!$F$5:$F$94,'Monthly Data'!$A$5:$A$94,$A12,'Monthly Data'!$C$5:$C$94,1081) -> 1 | D12: =SUMIFS('Monthly Data'!$F$5:$F$94,'Monthly Data'!$A$5:$A$94,$A12,'Monthly Data'!$C$5:$C$94,1082) -> 0 | E12: =SUMIFS('Monthly Data'!$F$5:$F$94,'Monthly Data'!$A$5:$A$94,$A12,'Monthly Data'!$C$5:$C$94,1084) -> 18 | F12: =SUMIFS('Monthly Data'!$F$5:$F$94,'Monthly Data'!$A$5:$A$94,$A12,'Monthly Data'!$C$5:$C$94,1085) -> 10 | G12: =SUM(B12:F12) -> 34
A13: 45992 | B13: =SUMIFS('Monthly Data'!$F$5:$F$94,'Monthly Data'!$A$5:$A$94,$A13,'Monthly Data'!$C$5:$C$94,1080) -> 13 | C13: =SUMIFS('Monthly Data'!$F$5:$F$94,'Monthly Data'!$A$5:$A$94,$A13,'Monthly Data'!$C$5:$C$94,1081) -> 1 | D13: =SUMIFS('Monthly Data'!$F$5:$F$94,'Monthly Data'!$A$5:$A$94,$A13,'Monthly Data'!$C$5:$C$94,1082) -> 0 | E13: =SUMIFS('Monthly Data'!$F$5:$F$94,'Monthly Data'!$A$5:$A$94,$A13,'Monthly Data'!$C$5:$C$94,1084) -> 14 | F13: =SUMIFS('Monthly Data'!$F$5:$F$94,'Monthly Data'!$A$5:$A$94,$A13,'Monthly Data'!$C$5:$C$94,1085) -> 18 | G13: =SUM(B13:F13) -> 46
A14: 46023 | B14: =SUMIFS('Monthly Data'!$F$5:$F$94,'Monthly Data'!$A$5:$A$94,$A14,'Monthly Data'!$C$5:$C$94,1080) -> 11 | C14: =SUMIFS('Monthly Data'!$F$5:$F$94,'Monthly Data'!$A$5:$A$94,$A14,'Monthly Data'!$C$5:$C$94,1081) -> 5 | D14: =SUMIFS('Monthly Data'!$F$5:$F$94,'Monthly Data'!$A$5:$A$94,$A14,'Monthly Data'!$C$5:$C$94,1082) -> 0 | E14: =SUMIFS('Monthly Data'!$F$5:$F$94,'Monthly Data'!$A$5:$A$94,$A14,'Monthly Data'!$C$5:$C$94,1084) -> 17 | F14: =SUMIFS('Monthly Data'!$F$5:$F$94,'Monthly Data'!$A$5:$A$94,$A14,'Monthly Data'!$C$5:$C$94,1085) -> 0 | G14: =SUM(B14:F14) -> 33
A15: 46054 | B15: =SUMIFS('Monthly Data'!$F$5:$F$94,'Monthly Data'!$A$5:$A$94,$A15,'Monthly Data'!$C$5:$C$94,1080) -> 8 | C15: =SUMIFS('Monthly Data'!$F$5:$F$94,'Monthly Data'!$A$5:$A$94,$A15,'Monthly Data'!$C$5:$C$94,1081) -> 2 | D15: =SUMIFS('Monthly Data'!$F$5:$F$94,'Monthly Data'!$A$5:$A$94,$A15,'Monthly Data'!$C$5:$C$94,1082) -> 0 | E15: =SUMIFS('Monthly Data'!$F$5:$F$94,'Monthly Data'!$A$5:$A$94,$A15,'Monthly Data'!$C$5:$C$94,1084) -> 21 | F15: =SUMIFS('Monthly Data'!$F$5:$F$94,'Monthly Data'!$A$5:$A$94,$A15,'Monthly Data'!$C$5:$C$94,1085) -> 0 | G15: =SUM(B15:F15) -> 31
A16: 46082 | B16: =SUMIFS('Monthly Data'!$F$5:$F$94,'Monthly Data'!$A$5:$A$94,$A16,'Monthly Data'!$C$5:$C$94,1080) -> 9 | C16: =SUMIFS('Monthly Data'!$F$5:$F$94,'Monthly Data'!$A$5:$A$94,$A16,'Monthly Data'!$C$5:$C$94,1081) -> 5 | D16: =SUMIFS('Monthly Data'!$F$5:$F$94,'Monthly Data'!$A$5:$A$94,$A16,'Monthly Data'!$C$5:$C$94,1082) -> 0 | E16: =SUMIFS('Monthly Data'!$F$5:$F$94,'Monthly Data'!$A$5:$A$94,$A16,'Monthly Data'!$C$5:$C$94,1084) -> 24 | F16: =SUMIFS('Monthly Data'!$F$5:$F$94,'Monthly Data'!$A$5:$A$94,$A16,'Monthly Data'!$C$5:$C$94,1085) -> 0 | G16: =SUM(B16:F16) -> 38
... A22: 46266 | B22: =SUMIFS('Monthly Data'!$F$5:$F$94,'Monthly Data'!$A$5:$A$94,$A22,'Monthly Data'!$C$5:$C$94,1080) -> 4 | C22: =SUMIFS('Monthly Data'!$F$5:$F$94,'Monthly Data'!$A$5:$A$94,$A22,'Monthly Data'!$C$5:$C$94,1081) -> 4 | D22: =SUMIFS('Monthly Data'!$F$5:$F$94,'Monthly Data'!$A$5:$A$94,$A22,'Monthly Data'!$C$5:$C$94,1082) -> 26 | E22: =SUMIFS('Monthly Data'!$F$5:$F$94,'Monthly Data'!$A$5:$A$94,$A22,'Monthly Data'!$C$5:$C$94,1084) -> 15 | F22: =SUMIFS('Monthly Data'!$F$5:$F$94,'Monthly Data'!$A$5:$A$94,$A22,'Monthly Data'!$C$5:$C$94,1085) -> 17 | G22: =SUM(B22:F22) -> 66
A23: Total | B23: =SUM(B5:B22) -> 170 | C23: =SUM(C5:C22) -> 67 | D23: =SUM(D5:D22) -> 226 | E23: =SUM(E5:E22) -> 361 | F23: =SUM(F5:F22) -> 173 | G23: =SUM(G5:G22) -> 997
A26: Credit card sales
A27: Month | B27: Fort Mill | C27: Lake Wylie | D27: Main | E27: York | F27: Clover | G27: Total
A28: 45748 | B28: =SUMIFS('Monthly Data'!$G$5:$G$94,'Monthly Data'!$A$5:$A$94,$A28,'Monthly Data'!$C$5:$C$94,1080) -> 38.2 | C28: =SUMIFS('Monthly Data'!$G$5:$G$94,'Monthly Data'!$A$5:$A$94,$A28,'Monthly Data'!$C$5:$C$94,1081) -> 24.32 | D28: =SUMIFS('Monthly Data'!$G$5:$G$94,'Monthly Data'!$A$5:$A$94,$A28,'Monthly Data'!$C$5:$C$94,1082) -> 176.3 | E28: =SUMIFS('Monthly Data'!$G$5:$G$94,'Monthly Data'!$A$5:$A$94,$A28,'Monthly Data'!$C$5:$C$94,1084) -> 177.73 | F28: =SUMIFS('Monthly Data'!$G$5:$G$94,'Monthly Data'!$A$5:$A$94,$A28,'Monthly Data'!$C$5:$C$94,1085) -> 70.77 | G28: =SUM(B28:F28) -> 487.32
A29: 45778 | B29: =SUMIFS('Monthly Data'!$G$5:$G$94,'Monthly Data'!$A$5:$A$94,$A29,'Monthly Data'!$C$5:$C$94,1080) -> 5.94 | C29: =SUMIFS('Monthly Data'!$G$5:$G$94,'Monthly Data'!$A$5:$A$94,$A29,'Monthly Data'!$C$5:$C$94,1081) -> 19.82 | D29: =SUMIFS('Monthly Data'!$G$5:$G$94,'Monthly Data'!$A$5:$A$94,$A29,'Monthly Data'!$C$5:$C$94,1082) -> 71.09 | E29: =SUMIFS('Monthly Data'!$G$5:$G$94,'Monthly Data'!$A$5:$A$94,$A29,'Monthly Data'!$C$5:$C$94,1084) -> 53.21 | F29: =SUMIFS('Monthly Data'!$G$5:$G$94,'Monthly Data'!$A$5:$A$94,$A29,'Monthly Data'!$C$5:$C$94,1085) -> 44.45 | G29: =SUM(B29:F29) -> 194.51
A30: 45809 | B30: =SUMIFS('Monthly Data'!$G$5:$G$94,'Monthly Data'!$A$5:$A$94,$A30,'Monthly Data'!$C$5:$C$94,1080) -> 57.39 | C30: =SUMIFS('Monthly Data'!$G$5:$G$94,'Monthly Data'!$A$5:$A$94,$A30,'Monthly Data'!$C$5:$C$94,1081) -> 104.84 | D30: =SUMIFS('Monthly Data'!$G$5:$G$94,'Monthly Data'!$A$5:$A$94,$A30,'Monthly Data'!$C$5:$C$94,1082) -> 77.16 | E30: =SUMIFS('Monthly Data'!$G$5:$G$94,'Monthly Data'!$A$5:$A$94,$A30,'Monthly Data'!$C$5:$C$94,1084) -> 130.6 | F30: =SUMIFS('Monthly Data'!$G$5:$G$94,'Monthly Data'!$A$5:$A$94,$A30,'Monthly Data'!$C$5:$C$94,1085) -> 66.02 | G30: =SUM(B30:F30) -> 436.01
A31: 45839 | B31: =SUMIFS('Monthly Data'!$G$5:$G$94,'Monthly Data'!$A$5:$A$94,$A31,'Monthly Data'!$C$5:$C$94,1080) -> 26.32 | C31: =SUMIFS('Monthly Data'!$G$5:$G$94,'Monthly Data'!$A$5:$A$94,$A31,'Monthly Data'!$C$5:$C$94,1081) -> 14.32 | D31: =SUMIFS('Monthly Data'!$G$5:$G$94,'Monthly Data'!$A$5:$A$94,$A31,'Monthly Data'!$C$5:$C$94,1082) -> 91.85 | E31: =SUMIFS('Monthly Data'!$G$5:$G$94,'Monthly Data'!$A$5:$A$94,$A31,'Monthly Data'!$C$5:$C$94,1084) -> 60.84 | F31: =SUMIFS('Monthly Data'!$G$5:$G$94,'Monthly Data'!$A$5:$A$94,$A31,'Monthly Data'!$C$5:$C$94,1085) -> 92.65 | G31: =SUM(B31:F31) -> 285.98
A32: 45870 | B32: =SUMIFS('Monthly Data'!$G$5:$G$94,'Monthly Data'!$A$5:$A$94,$A32,'Monthly Data'!$C$5:$C$94,1080) -> 51.96 | C32: =SUMIFS('Monthly Data'!$G$5:$G$94,'Monthly Data'!$A$5:$A$94,$A32,'Monthly Data'!$C$5:$C$94,1081) -> 11.63 | D32: =SUMIFS('Monthly Data'!$G$5:$G$94,'Monthly Data'!$A$5:$A$94,$A32,'Monthly Data'!$C$5:$C$94,1082) -> 133.29 | E32: =SUMIFS('Monthly Data'!$G$5:$G$94,'Monthly Data'!$A$5:$A$94,$A32,'Monthly Data'!$C$5:$C$94,1084) -> 138.47 | F32: =SUMIFS('Monthly Data'!$G$5:$G$94,'Monthly Data'!$A$5:$A$94,$A32,'Monthly Data'!$C$5:$C$94,1085) -> 54.39 | G32: =SUM(B32:F32) -> 389.74
A33: 45901 | B33: =SUMIFS('Monthly Data'!$G$5:$G$94,'Monthly Data'!$A$5:$A$94,$A33,'Monthly Data'!$C$5:$C$94,1080) -> 39.71 | C33: =SUMIFS('Monthly Data'!$G$5:$G$94,'Monthly Data'!$A$5:$A$94,$A33,'Monthly Data'!$C$5:$C$94,1081) -> 5.19 | D33: =SUMIFS('Monthly Data'!$G$5:$G$94,'Monthly Data'!$A$5:$A$94,$A33,'Monthly Data'!$C$5:$C$94,1082) -> 110.47 | E33: =SUMIFS('Monthly Data'!$G$5:$G$94,'Monthly Data'!$A$5:$A$94,$A33,'Monthly Data'!$C$5:$C$94,1084) -> 52.47 | F33: =SUMIFS('Monthly Data'!$G$5:$G$94,'Monthly Data'!$A$5:$A$94,$A33,'Monthly Data'!$C$5:$C$94,1085) -> 97.59 | G33: =SUM(B33:F33) -> 305.43
A34: 45931 | B34: =SUMIFS('Monthly Data'!$G$5:$G$94,'Monthly Data'!$A$5:$A$94,$A34,'Monthly Data'!$C$5:$C$94,1080) -> 83.65 | C34: =SUMIFS('Monthly Data'!$G$5:$G$94,'Monthly Data'!$A$5:$A$94,$A34,'Monthly Data'!$C$5:$C$94,1081) -> 17.63 | D34: =SUMIFS('Monthly Data'!$G$5:$G$94,'Monthly Data'!$A$5:$A$94,$A34,'Monthly Data'!$C$5:$C$94,1082) -> 0 | E34: =SUMIFS('Monthly Data'!$G$5:$G$94,'Monthly Data'!$A$5:$A$94,$A34,'Monthly Data'!$C$5:$C$94,1084) -> 87.98 | F34: =SUMIFS('Monthly Data'!$G$5:$G$94,'Monthly Data'!$A$5:$A$94,$A34,'Monthly Data'!$C$5:$C$94,1085) -> 30.08 | G34: =SUM(B34:F34) -> 219.34
A35: 45962 | B35: =SUMIFS('Monthly Data'!$G$5:$G$94,'Monthly Data'!$A$5:$A$94,$A35,'Monthly Data'!$C$5:$C$94,1080) -> 24.51 | C35: =SUMIFS('Monthly Data'!$G$5:$G$94,'Monthly Data'!$A$5:$A$94,$A35,'Monthly Data'!$C$5:$C$94,1081) -> 2.44 | D35: =SUMIFS('Monthly Data'!$G$5:$G$94,'Monthly Data'!$A$5:$A$94,$A35,'Monthly Data'!$C$5:$C$94,1082) -> 0 | E35: =SUMIFS('Monthly Data'!$G$5:$G$94,'Monthly Data'!$A$5:$A$94,$A35,'Monthly Data'!$C$5:$C$94,1084) -> 95.09 | F35: =SUMIFS('Monthly Data'!$G$5:$G$94,'Monthly Data'!$A$5:$A$94,$A35,'Monthly Data'!$C$5:$C$94,1085) -> 44.71 | G35: =SUM(B35:F35) -> 166.75
A36: 45992 | B36: =SUMIFS('Monthly Data'!$G$5:$G$94,'Monthly Data'!$A$5:$A$94,$A36,'Monthly Data'!$C$5:$C$94,1080) -> 91.65 | C36: =SUMIFS('Monthly Data'!$G$5:$G$94,'Monthly Data'!$A$5:$A$94,$A36,'Monthly Data'!$C$5:$C$94,1081) -> 13.44 | D36: =SUMIFS('Monthly Data'!$G$5:$G$94,'Monthly Data'!$A$5:$A$94,$A36,'Monthly Data'!$C$5:$C$94,1082) -> 0 | E36: =SUMIFS('Monthly Data'!$G$5:$G$94,'Monthly Data'!$A$5:$A$94,$A36,'Monthly Data'!$C$5:$C$94,1084) -> 88.4 | F36: =SUMIFS('Monthly Data'!$G$5:$G$94,'Monthly Data'!$A$5:$A$94,$A36,'Monthly Data'!$C$5:$C$94,1085) -> 89.54 | G36: =SUM(B36:F36) -> 283.03
A37: 46023 | B37: =SUMIFS('Monthly Data'!$G$5:$G$94,'Monthly Data'!$A$5:$A$94,$A37,'Monthly Data'!$C$5:$C$94,1080) -> 55.77 | C37: =SUMIFS('Monthly Data'!$G$5:$G$94,'Monthly Data'!$A$5:$A$94,$A37,'Monthly Data'!$C$5:$C$94,1081) -> 45.82 | D37: =SUMIFS('Monthly Data'!$G$5:$G$94,'Monthly Data'!$A$5:$A$94,$A37,'Monthly Data'!$C$5:$C$94,1082) -> 0 | E37: =SUMIFS('Monthly Data'!$G$5:$G$94,'Monthly Data'!$A$5:$A$94,$A37,'Monthly Data'!$C$5:$C$94,1084) -> 117.1 | F37: =SUMIFS('Monthly Data'!$G$5:$G$94,'Monthly Data'!$A$5:$A$94,$A37,'Monthly Data'!$C$5:$C$94,1085) -> 0 | G37: =SUM(B37:F37) -> 218.69
A38: 46054 | B38: =SUMIFS('Monthly Data'!$G$5:$G$94,'Monthly Data'!$A$5:$A$94,$A38,'Monthly Data'!$C$5:$C$94,1080) -> 46.7 | C38: =SUMIFS('Monthly Data'!$G$5:$G$94,'Monthly Data'!$A$5:$A$94,$A38,'Monthly Data'!$C$5:$C$94,1081) -> 10.19 | D38: =SUMIFS('Monthly Data'!$G$5:$G$94,'Monthly Data'!$A$5:$A$94,$A38,'Monthly Data'!$C$5:$C$94,1082) -> 0 | E38: =SUMIFS('Monthly Data'!$G$5:$G$94,'Monthly Data'!$A$5:$A$94,$A38,'Monthly Data'!$C$5:$C$94,1084) -> 75.72 | F38: =SUMIFS('Monthly Data'!$G$5:$G$94,'Monthly Data'!$A$5:$A$94,$A38,'Monthly Data'!$C$5:$C$94,1085) -> 0 | G38: =SUM(B38:F38) -> 132.61
A39: 46082 | B39: =SUMIFS('Monthly Data'!$G$5:$G$94,'Monthly Data'!$A$5:$A$94,$A39,'Monthly Data'!$C$5:$C$94,1080) -> 64.58 | C39: =SUMIFS('Monthly Data'!$G$5:$G$94,'Monthly Data'!$A$5:$A$94,$A39,'Monthly Data'!$C$5:$C$94,1081) -> 18.51 | D39: =SUMIFS('Monthly Data'!$G$5:$G$94,'Monthly Data'!$A$5:$A$94,$A39,'Monthly Data'!$C$5:$C$94,1082) -> 0 | E39: =SUMIFS('Monthly Data'!$G$5:$G$94,'Monthly Data'!$A$5:$A$94,$A39,'Monthly Data'!$C$5:$C$94,1084) -> 125.8 | F39: =SUMIFS('Monthly Data'!$G$5:$G$94,'Monthly Data'!$A$5:$A$94,$A39,'Monthly Data'!$C$5:$C$94,1085) -> 0 | G39: =SUM(B39:F39) -> 208.89
... A45: 46266 | B45: =SUMIFS('Monthly Data'!$G$5:$G$94,'Monthly Data'!$A$5:$A$94,$A45,'Monthly Data'!$C$5:$C$94,1080) -> 16.76 | C45: =SUMIFS('Monthly Data'!$G$5:$G$94,'Monthly Data'!$A$5:$A$94,$A45,'Monthly Data'!$C$5:$C$94,1081) -> 25.76 | D45: =SUMIFS('Monthly Data'!$G$5:$G$94,'Monthly Data'!$A$5:$A$94,$A45,'Monthly Data'!$C$5:$C$94,1082) -> 150.41 | E45: =SUMIFS('Monthly Data'!$G$5:$G$94,'Monthly Data'!$A$5:$A$94,$A45,'Monthly Data'!$C$5:$C$94,1084) -> 85.46 | F45: =SUMIFS('Monthly Data'!$G$5:$G$94,'Monthly Data'!$A$5:$A$94,$A45,'Monthly Data'!$C$5:$C$94,1085) -> 98.27 | G45: =SUM(B45:F45) -> 376.66
A46: Total | B46: =SUM(B28:B45) -> 917.9 | C46: =SUM(C28:C45) -> 412.51 | D46: =SUM(D28:D45) -> 1194.27 | E46: =SUM(E28:E45) -> 2047.93 | F46: =SUM(F28:F45) -> 860.67 | G46: =SUM(G28:G45) -> 5433.28
A49: Commission
A50: Month | B50: Fort Mill | C50: Lake Wylie | D50: Main | E50: York | F50: Clover | G50: Total
A51: 45748 | B51: =SUMIFS('Monthly Data'!$H$5:$H$94,'Monthly Data'!$A$5:$A$94,$A51,'Monthly Data'!$C$5:$C$94,1080) -> 0 | C51: =SUMIFS('Monthly Data'!$H$5:$H$94,'Monthly Data'!$A$5:$A$94,$A51,'Monthly Data'!$C$5:$C$94,1081) -> 0 | D51: =SUMIFS('Monthly Data'!$H$5:$H$94,'Monthly Data'!$A$5:$A$94,$A51,'Monthly Data'!$C$5:$C$94,1082) -> 17.76 | E51: =SUMIFS('Monthly Data'!$H$5:$H$94,'Monthly Data'!$A$5:$A$94,$A51,'Monthly Data'!$C$5:$C$94,1084) -> 18.05 | F51: =SUMIFS('Monthly Data'!$H$5:$H$94,'Monthly Data'!$A$5:$A$94,$A51,'Monthly Data'!$C$5:$C$94,1085) -> 1.04 | G51: =SUM(B51:F51) -> 36.85
A52: 45778 | B52: =SUMIFS('Monthly Data'!$H$5:$H$94,'Monthly Data'!$A$5:$A$94,$A52,'Monthly Data'!$C$5:$C$94,1080) -> 0 | C52: =SUMIFS('Monthly Data'!$H$5:$H$94,'Monthly Data'!$A$5:$A$94,$A52,'Monthly Data'!$C$5:$C$94,1081) -> 0 | D52: =SUMIFS('Monthly Data'!$H$5:$H$94,'Monthly Data'!$A$5:$A$94,$A52,'Monthly Data'!$C$5:$C$94,1082) -> 1.05 | E52: =SUMIFS('Monthly Data'!$H$5:$H$94,'Monthly Data'!$A$5:$A$94,$A52,'Monthly Data'!$C$5:$C$94,1084) -> 0.16 | F52: =SUMIFS('Monthly Data'!$H$5:$H$94,'Monthly Data'!$A$5:$A$94,$A52,'Monthly Data'!$C$5:$C$94,1085) -> 0 | G52: =SUM(B52:F52) -> 1.21
A53: 45809 | B53: =SUMIFS('Monthly Data'!$H$5:$H$94,'Monthly Data'!$A$5:$A$94,$A53,'Monthly Data'!$C$5:$C$94,1080) -> 0.37 | C53: =SUMIFS('Monthly Data'!$H$5:$H$94,'Monthly Data'!$A$5:$A$94,$A53,'Monthly Data'!$C$5:$C$94,1081) -> 3.47 | D53: =SUMIFS('Monthly Data'!$H$5:$H$94,'Monthly Data'!$A$5:$A$94,$A53,'Monthly Data'!$C$5:$C$94,1082) -> 1.36 | E53: =SUMIFS('Monthly Data'!$H$5:$H$94,'Monthly Data'!$A$5:$A$94,$A53,'Monthly Data'!$C$5:$C$94,1084) -> 8.62 | F53: =SUMIFS('Monthly Data'!$H$5:$H$94,'Monthly Data'!$A$5:$A$94,$A53,'Monthly Data'!$C$5:$C$94,1085) -> 0.8 | G53: =SUM(B53:F53) -> 14.62
A54: 45839 | B54: =SUMIFS('Monthly Data'!$H$5:$H$94,'Monthly Data'!$A$5:$A$94,$A54,'Monthly Data'!$C$5:$C$94,1080) -> 0 | C54: =SUMIFS('Monthly Data'!$H$5:$H$94,'Monthly Data'!$A$5:$A$94,$A54,'Monthly Data'!$C$5:$C$94,1081) -> 0 | D54: =SUMIFS('Monthly Data'!$H$5:$H$94,'Monthly Data'!$A$5:$A$94,$A54,'Monthly Data'!$C$5:$C$94,1082) -> 2.09 | E54: =SUMIFS('Monthly Data'!$H$5:$H$94,'Monthly Data'!$A$5:$A$94,$A54,'Monthly Data'!$C$5:$C$94,1084) -> 0.54 | F54: =SUMIFS('Monthly Data'!$H$5:$H$94,'Monthly Data'!$A$5:$A$94,$A54,'Monthly Data'!$C$5:$C$94,1085) -> 2.13 | G54: =SUM(B54:F54) -> 4.76
A55: 45870 | B55: =SUMIFS('Monthly Data'!$H$5:$H$94,'Monthly Data'!$A$5:$A$94,$A55,'Monthly Data'!$C$5:$C$94,1080) -> 0.1 | C55: =SUMIFS('Monthly Data'!$H$5:$H$94,'Monthly Data'!$A$5:$A$94,$A55,'Monthly Data'!$C$5:$C$94,1081) -> 0 | D55: =SUMIFS('Monthly Data'!$H$5:$H$94,'Monthly Data'!$A$5:$A$94,$A55,'Monthly Data'!$C$5:$C$94,1082) -> 9.16 | E55: =SUMIFS('Monthly Data'!$H$5:$H$94,'Monthly Data'!$A$5:$A$94,$A55,'Monthly Data'!$C$5:$C$94,1084) -> 10.19 | F55: =SUMIFS('Monthly Data'!$H$5:$H$94,'Monthly Data'!$A$5:$A$94,$A55,'Monthly Data'!$C$5:$C$94,1085) -> 0.22 | G55: =SUM(B55:F55) -> 19.67
...

Sheet Source Files
A1: How each of the 17 PDFs in the Faxing folder was used
A3: File (prefix 'York County Library Mail - ' omitted) | B3: Report Type | C3: Data Period | D3: Email Date | E3: How Used
A4: Quarterly Public Fax24 for Group York County Fort Mill Branch QUARTYER 2.pdf | B4: Quarterly (old format) | C4: Apr–Jun 2025 | D4: 2025-07-01 | E4: Used: Apr, May, Jun 2025 rows
A5: Public Fax24 for Group 225 ... Main Bran AUG.pdf | B5: Monthly (old format) | C5: Jul 2025 | D5: 2025-08-01 | E5: Duplicate of Q3 2025 quarterly (figures match); not counted
A6: Public Fax24 for Group 225 ... Main Bran 2.pdf | B6: Monthly (old format) | C6: Aug 2025 | D6: 2025-09-01 | E6: Duplicate of Q3 2025 quarterly (figures match); not counted
A7: Quarterly Public Fax24 for Group York County Fort Mill Branch OCT.pdf | B7: Quarterly (old format) | C7: Jul–Sep 2025 | D7: 2025-10-01 | E7: Used: Jul, Aug, Sep 2025 rows
A8: Public Fax24 for Group 225 ... Main Bran NOV.pdf | B8: Monthly (old format) | C8: Oct 2025 | D8: 2025-11-01 | E8: Duplicate of Q4 2025 quarterly (figures match); not counted
A9: Public Fax24 for Group 225 ... Main Bran.pdf | B9: Monthly (old format) | C9: Nov 2025 | D9: 2025-12-01 | E9: Duplicate of Q4 2025 quarterly (figures match); not counted
A10: Quarterly Public Fax24 for Group York County Fort Mill Branch.pdf | B10: Quarterly (old format) | C10: Oct–Dec 2025 | D10: 2026-01-01 | E10: Used: Oct, Nov, Dec 2025 rows
A11: FaxScan24 Monthly Activity Report — 01_01_2026 to 01_31_2026 (Group 225).pdf | B11: Monthly (new format) | C11: Jan 2026 | D11: 2026-02-03 | E11: Used: Jan 2026 rows
A12: FaxScan24 Monthly Activity Report — 02_01_2026 to 02_28_2026 (Group 225).pdf | B12: Monthly (new format) | C12: Feb 2026 | D12: 2026-03-02 | E12: Used: Feb 2026 rows
A13: FaxScan24 Monthly Activity Report — 03_01_2026 to 03_31_2026 (Group 225).pdf | B13: Monthly (new format) | C13: Mar 2026 | D13: 2026-04-02 | E13: Used: Mar 2026 rows
A14: FaxScan24 Monthly Activity Report — 04_01_2026 to 04_30_2026 (Group 225).pdf | B14: Monthly (new format) | C14: Apr 2026 | D14: 2026-05-04 | E14: Used: Apr 2026 rows
... A20: FaxScan24 Activity Report — 07_01_2026 to 09_30_2026 (Group 225).pdf | B20: Quarterly (new format) | C20: Jul–Sep 2026 | D20: 2026-10-05 | E20: Duplicate of Jul–Sep 2026 monthly reports; used only as a check
A23: Note: old-format monthly file names (AUG, NOV, 2) refer to the month the email arrived, not the month of the data.
