Workbook
Name BranchStatsData: OFFSET('Branch Stats'!$B$1,0,0,COUNTA('Branch Stats'!$A:$A),COUNTA('Branch Stats'!$1:$1)-1)
Name OnlineStatsData: 'Online Stats'!$A$1:$AB$1759

Sheet Notes
A1: Perfect! Here's how to make that specific range dynamic:
A3: Step-by-Step for Your Range
A5: 1. Open Name Manager
A7: Go to Formulas tab > Name Manager
A8: Click New
A10: 2. Create the Dynamic Named Range
A12: Name: BranchStatsData (or whatever you prefer)
A13: Refers to: Use this formula:
A15: =OFFSET('Branch Stats'!$B$1,0,0,COUNTA('Branch Stats'!$A:$A),COUNTA('Branch Stats'!$1:$1)-1) -> #VALUE!
A17: What this does:
A19: Starts at cell B1
A20: COUNTA('Branch Stats'!$B:$B) - Automatically counts how many rows have data in column B (grows from 234 as you add data)
A21: COUNTA('Branch Stats'!$1:$1)-1 - Counts columns in row 1, minus 1 (since you start at B, not A) - maintains your ~57 columns (B to BD)
A23: 3. Update Your Pivot Table
A25: Click anywhere in your pivot table
A26: Go to PivotTable Analyze tab > Change Data Source
A27: Replace the current range with: =BranchStatsData
A28: Click OK
A30: Now whenever you paste new rows below row 234, the range will automatically expand, and you just need to refresh the pivot table (right-click > Refresh or Alt+F5) to see the new data!
A32: Does your data always start in row 1 with headers, or do you need any adjustments to this formula?

Sheet Dash Board
A1: Section | B1: State Library Annual Statistical Report
A2: LIBRARY USERS, VISITS, AND INTERNET USAGE
A3: G1 | B3: Registered Users, Adult | C3: =SUM('Circ Door Cnt Cards'!J18) -> 3942
A4: G2 | B4: Registered Users, Juvenile | C4: =SUM('Circ Door Cnt Cards'!K18) -> 2079
A5: G4 | B5: Gate Count | C5: =SUM('Circ Door Cnt Cards'!E18) -> 635801
A6: G6 | B6: Public Interent Computer Use | C6: =SUM('Tech Use'!G11) -> 19403
A7: G9 | B7: WiFI Sessions Annual | C7: =SUM('Tech Use'!H11) -> 42830
A8: G11 | B8: Website Visits | C8: =SUM('Online use'!H14) -> 268905
A9: G12 | B9: External Party Meeting Room Use
A10: REFERENCE, CIRCLUATION
A11: H1 | B11: Annual Reference Transactions
A12: H3 | B12: 1on1 Sessions
A13: H4 | B13: Children's Print Circ
A14: H5 | B14: Children's Non-Print Circ
A15: H7 | B15: Adult Print Circ
A16: H8 | B16: Adult Non-Print Circ
A17: H10 | B17: Circ of Other Physical Materials
A18: H14 | B18: Ebook Circ
A19: H15 | B19: EAudio Circ
A20: H16 | B20: EVideo Circ
A21: H17 | B21: ESerial Circulation
A22: H20 | B22: ILLs Sent
A23: H21 | B23: ILLs Received
A24: PROGRAMMING
A25: SESSIONS
A26: ONSITE | B26: Programs 0-5 | C26: =SUM('Programs Month'!$B$6) -> 151
A27: ONSITE | B27: Programs 6-11 | C27: =SUM('Programs Month'!$C$6) -> 32
A28: ONSITE | B28: Programs 12-18 | C28: =SUM('Programs Month'!$D$6) -> 39
A29: ONSITE | B29: Programs 19+ | C29: =SUM('Programs Month'!$E$6) -> 105
A30: ONSITE | B30: Programs General Interest | C30: =SUM('Programs Month'!$F$6) -> 17
A31: OFFSITE | B31: Programs 0-5 | C31: =SUM(GETPIVOTDATA("Sum of OFFSITE Sessions 0-5",'Programs Month'!$A$19)) -> 0
A32: OFFSITE | B32: Programs 6-11 | C32: =SUM(GETPIVOTDATA("Sum of OFFSITE Sessions 6-11",'Programs Month'!$A$19)) -> 56
A33: OFFSITE | B33: Programs 12-18 | C33: =SUM(GETPIVOTDATA("Sum of OFFSITE Sessions 12-18",'Programs Month'!$A$19)) -> 0
A34: OFFSITE | B34: Programs 19+ | C34: =SUM(GETPIVOTDATA("Sum of OFFSITE Sessions 19+",'Programs Month'!$A$19)) -> 0
A35: OFFSITE | B35: Programs General Interest | C35: =SUM(GETPIVOTDATA("Sum of OFFSITE Sessions General Interest",'Programs Month'!$A$19)) -> 0
A36: VIRTUAL | B36: Programs 0-5 | C36: =SUM(GETPIVOTDATA("Sum of VIRTUAL Sessions 0-5",'Programs Month'!$A$30)) -> 0
A37: VIRTUAL | B37: Programs 6-11 | C37: =SUM(GETPIVOTDATA("Sum of VIRTUAL Sessions 6-11",'Programs Month'!$A$30)) -> 0
A38: VIRTUAL | B38: Programs 12-18 | C38: =SUM(GETPIVOTDATA("Sum of VIRTUAL Sessions 12-18",'Programs Month'!$A$30)) -> 0
A39: VIRTUAL | B39: Programs 19+ | C39: =SUM('Programs Month'!$D$31) -> 0
A40: VIRTUAL | B40: Programs General Interest | C40: =SUM(GETPIVOTDATA("Sum of VIRTUAL Sessions General Interest",'Programs Month'!$A$30)) -> 0
...

Sheet Other 2025 Stats
A1: Month | B1: (All)
A3: Row Labels | B3: Sum of 1-on-1 Total for Month | C3: Sum of I22: TOTAL # TAKE & MAKES and OTHER PASSIVE PROGRAM PARTICIPANTS | D3: Sum of Outreach Attendance (YCL Internal) | E3: Sum of I23: NUMBER OF STAFF TAKING TRAINING | F3: Sum of I24: NUMBER OF HOURS STAFF ATTENDED TRAINING | G3: Sum of I21: NUMBER OF OUTREACH ACTIVITIES Conducted | H3: Sum of External Party Library Room Use | I3: Sum of ILL - Sent (Main ONLY) | J3: Sum of ILL - Received (Main ONLY)
A4: 2024 | B4: 193 | C4: 13986 | E4: 593 | F4: 2255.5 | H4: 236 | I4: 178 | J4: 1227
A5: 2025 | B5: 93 | C5: 7358 | D5: 334 | E5: 463 | F5: 2060.05 | G5: 7 | H5: 200 | I5: 28 | J5: 918
A6: Grand Total | B6: 286 | C6: 21344 | D6: 334 | E6: 1056 | F6: 4315.55 | G6: 7 | H6: 436 | I6: 206 | J6: 2145
A11: Meeting Room Use
B12: Column Labels
B13: 2025 | C13: (blank) | D13: Grand Total
A14: Sum of External Party Library Room Use | B14: 353 | D14: 353
A17: 1on1s
A18: Row Labels | B18: Sum of 1-on-1 Total for Month
A19: 2024 | B19: 193
A20: 2025 | B20: 157
A21: (blank)
A22: 2026 | B22: 25
A23: Grand Total | B23: 375

Sheet Asynch
A1: Month | B1: (All)
A3: Row Labels | B3: Sum of Dial A Story Uploads | C3: Sum of Dial A Story - VIEWS | D3: Sum of YouTube Uploads | E3: Sum of YouTube - Views
A4: 2024 | E4: 42105
A5: 2025 | B5: 89 | C5: 523 | D5: 9 | E5: 7503
A6: Grand Total | B6: 89 | C6: 523 | D6: 9 | E6: 49608
B8: Sessions | C8: Views
A9: 2025 | B9: =SUM(GETPIVOTDATA("Sum of Dial A Story Uploads",$A$3,"Year",2025)+GETPIVOTDATA("Sum of YouTube Uploads",$A$3,"Year",2025)) -> 98 | C9: =SUM(GETPIVOTDATA("Sum of Dial A Story - VIEWS",$A$3,"Year",2025)+GETPIVOTDATA("Sum of YouTube - Views",$A$3,"Year",2025)) -> 8026

Sheet Circ Door Cnt Cards
A1: Month | B1: (Multiple Items) | E1: Month Num | F1: (All) | J1: Month | K1: (Multiple Items) | M1: Year | N1: 2026
A2: Month Num | B2: (All) | E2: Year | F2: 2026 | J2: Year | K2: 2025 | M2: Month | N2: (Multiple Items) | Q2: Month | R2: (Multiple Items)
A3: Year | B3: 2025 | E3: Month | F3: (Multiple Items)
J4: Sum of New Library Card Registrations, Adult (includes YA) | K4: Sum of New Library Card Registrations, Juvenile | M4: Sum of New Library Card Registrations, Adult (includes YA) | N4: Sum of New Library Card Registrations, Juvenile | Q4: Row Labels | R4: New Library Cards, Adult (includes YA) | S4: New Library Cards, Juvenile
A5: Monthly Circulation | B5: Monthly Gate Count | C5: Locker Checkouts | E5: Monthly Circulation | F5: Monthly Gate Count | G5: Monthly Locker Circulation | J5: 2785 | K5: 1271 | M5: 1157 | N5: 808 | Q5: 2025 | R5: 3806 | S5: 1696
A6: 450958 | B6: 189265 | C6: 8273 | E6: 184843 | F6: 75486 | G6: 2279 | Q6: 2026 | R6: 1157 | S6: 808
Q7: Grand Total | R7: 4963 | S7: 2504
A11: Board Stats
E15: Fiscal Year Totals | J15: Fiscal Year Totals
E16: 25-26 Totals | J16: 25-26 Totals
E17: Annual Circulation | F17: Annual Gate Count | G17: Annual Locker Checkouts | J17: Adult Library Cards | K17: Juvenile Library Cards
E18: =SUM(GETPIVOTDATA("Monthly Circulation",$A$5)+GETPIVOTDATA("Monthly Circulation",$E$5)) -> 635801 | F18: =SUM(GETPIVOTDATA("Monthly Gate Count",$A$5)+GETPIVOTDATA("Monthly Gate Count",$E$5)) -> 264751 | G18: =SUM(GETPIVOTDATA("Locker Checkouts",$A$5)+GETPIVOTDATA("Monthly Locker Circulation",$E$5)) -> 10552 | J18: =SUM(GETPIVOTDATA("Sum of New Library Card Registrations, Adult (includes YA)",$J$4)+GETPIVOTDATA("Sum of New Library Card Registrations, Adult (includes YA)",$M$4)) -> 3942 | K18: =SUM(GETPIVOTDATA("Sum of New Library Card Registrations, Juvenile",$J$4)+GETPIVOTDATA("Sum of New Library Card Registrations, Juvenile",$M$4)) -> 2079
A31: Month | B31: March
A33: Row Labels | B33: Monthly Branch Circulation | C33: Monthly Gate Count | D33: Monthly Locker Circulation
A34: 2025 | B34: 49005 | C34: 38585
A35: 2026 | B35: 66759 | C35: 26733 | D35: 640
A36: Grand Total | B36: 115764 | C36: 65318 | D36: 640

Sheet Circ Data Test
A1: Year | B1: 2026
A3: Row Labels | B3: Sum of Total Branch Circulation
A4: CLOVER | B4: 14594
A5: January | B5: 4823
A6: February | B6: 4894
A7: March | B7: 4877
A8: FORT MILL | B8: 122553
A9: January | B9: 40953
A10: February | B10: 39230
A11: March | B11: 42370
A12: LAKE WYLIE | B12: 14725
A13: January | B13: 5708
A14: February | B14: 4042
A15: March | B15: 4975
A16: OUTREACH / BOOKMOBILE | B16: 5444
A17: January
A18: February | B18: 2226
A19: March | B19: 3218
A20: ROCK HILL | B20: 4700
A21: January | B21: 992
A22: March | B22: 3708
A23: YORK | B23: 22827
A24: January | B24: 7362
A25: February | B25: 7854
A26: March | B26: 7611
A27: Grand Total | B27: 184843

Sheet ICLs
A1: Month | B1: (Multiple Items) | D1: Month | E1: (Multiple Items)
A2: Year | B2: 2025 | D2: Year | E2: 2026
A4: ICLs Received | B4: ICLs Sent | D4: ICLs Received | E4: ICLs Sent
A5: 33264 | B5: 12977 | D5: 12873 | E5: 2065
A7: Fiscal Year
A8: 25-26 Totals
A9: ICLs Received | B9: ICLs Sent
A10: =SUM(GETPIVOTDATA("ICLs Received",$A$4)+GETPIVOTDATA("ICLs Received",$D$4)) -> 46137 | B10: =SUM(GETPIVOTDATA("ICLs Sent",$A$4)+GETPIVOTDATA("ICLs Sent",$D$4)) -> 15042
A12: Total | B12: =SUM(A10+B10) -> 61179

Sheet eResources Use
A1: 25-26 Fiscal Year
A4: Children's Databases
A5: Year | B5: 2025
A7: Sum of ABCmouse | B7: Sum of Lote4Kids - Activities | C7: Sum of Lote4Kids - Logins | D7: Sum of Year
A8: 436 | B8: 2 | C8: 50 | D8: 8100
A12: Statistics and Financials
A13: Year | B13: 2025
A15: Sum of Data Axle/Reference USA | B15: Sum of ValueLine Searches | C15: Sum of Weiss Page Views | D15: Sum of Weiss Searches | E15: Sum of Weiss Sessions
A16: 1044 | B16: 32101 | C16: 73 | D16: 3 | E16: 58
A21: Flipster
A22: Year | B22: 2025
A24: Sum of Flipster Searches | B24: Sum of Flipster Sessions | C24: Sum of Kanopy Plays | D24: Sum of Kanopy Sessions/Views
A25: 372 | B25: 326 | C25: 3385 | D25: 15701
A28: Gale / Udemy / Infobase
A29: Year | B29: 2025
A31: Sum of Gale eBooks | B31: Sum of Gale Udemy | C31: Sum of Infobase: The Mailbox Searches | D31: Sum of Infobase: The Mailbox Sessions
A32: 27 | B32: 327 | C32: 60 | D32: 18
A37: LibraryAware
A38: Year | B38: 2025
A40: Sum of Library Aware: Newsletter Page Views | B40: Sum of Library Aware: Newsletter Subscriptions
A41: 3563 | B41: 3864
A44: Mango
A45: Year | B45: 2025
A47: Sum of Mango
A48: 974
A51: Hoopla
A52: Year | B52: 2025
A54: Sum of hoopla Binge Passes | B54: Sum of hoopla Comics | C54: Sum of hoopla Flex eAudio | D54: Sum of hoopla Flex eBook | E54: Sum of hoopla Instant eAudio | F54: Sum of hoopla Instant eBook | G54: Sum of hoopla Movies | H54: Sum of hoopla Music | I54: Sum of hoopla TV
A55: 455 | B55: 2192 | C55: 15449 | D55: 3196 | E55: 39270 | F55: 10339 | G55: 2696 | H55: 2876 | I55: 1160
A58: Libby
A59: Year | B59: (All)
A61: Sum of Libby eAudio | B61: Sum of Libby eBook | C61: Sum of Libby Magazines | D61: Sum of Libby Streaming
A62: 31421 | B62: 59610 | C62: 16636 | D62: 32
A66: Proquest
A67: Year | B67: 2025
A69: Sum of Proquest: Heritage Quest Online | B69: Sum of Proquest: Fold3 | C69: Sum of Proquest: Ancestry Library Edition
A70: 1367 | B70: 711 | C70: 4541
A74: Tutoring
A75: Year | B75: 2025
A77: Sum of Tutor | B77: Sum of Brainfuse
...

Sheet Programs Month
A1: Month | B1: March
A3: Row Labels | B3: Sessions 0-5 | C3: Sessions 6-11 | D3: Sessions 12-18 | E3: Sessions 19+ | F3: Sessions GENERAL INTEREST
A4: 2025 | B4: 93 | C4: 15 | D4: 25 | E4: 68 | F4: 13
A5: 2026 | B5: 58 | C5: 17 | D5: 14 | E5: 37 | F5: 4
A6: Grand Total | B6: 151 | C6: 32 | D6: 39 | E6: 105 | F6: 17
A8: Month | B8: March
A10: Row Labels | B10: Attendance 0-5 | C10: Attendance 6-11 | D10: Attendance 12-18 | E10: Attendance 19+ | F10: Attendance General Interest
A11: 2025 | B11: 2633 | C11: 229 | D11: 264 | E11: 636 | F11: 277
A12: 2026 | B12: 1822 | C12: 206 | D12: 120 | E12: 328 | F12: 230
A13: Grand Total | B13: 4455 | C13: 435 | D13: 384 | E13: 964 | F13: 507
A16: OFFSITE
A17: Year | B17: 2024
A19: Sum of OFFSITE Sessions 0-5 | B19: Sum of OFFSITE Sessions 6-11 | C19: Sum of OFFSITE Sessions 12-18 | D19: Sum of OFFSITE Sessions 19+ | E19: Sum of OFFSITE Sessions General Interest
B20: 56
A22: Year | B22: 2026
A24: Sum of OFFSITE Attendance 0-5 | B24: Sum of OFFSITE Attendance 6-11 | C24: Sum of OFFSITE Attendance 12-18 | D24: Sum of OFFSITE Attendance 19+ | E24: Sum of OFFSITE Attendance General Interest
A25: 496 | B25: 57 | C25: 270 | D25: 121 | E25: 196
A27: VIRTUAL
A28: Year | B28: 2024
A30: Sum of VIRTUAL Sessions 0-5 | B30: Sum of VIRTUAL Sessions 6-11 | C30: Sum of VIRTUAL Sessions 12-18 | D30: Sum of VIRTUAL Sessions 19+ | E30: Sum of VIRTUAL Sessions General Interest
A32: Year | B32: 2024
A34: Sum of VIRTUAL Attendance 0-5 | B34: Sum of VIRTUAL Attendance 6-11 | C34: Sum of VIRTUAL Attendance 12-18 | D34: Sum of VIRTUAL Attendance 19+ | E34: Sum of VIRTUAL Attendance General Interest

Sheet Prog Annual
A1: Month | B1: (Multiple Items) | I1: Month | J1: (Multiple Items)
A3: Row Labels | B3: Sessions 0-5 | C3: Sessions 6-11 | D3: Sessions 12-18 | E3: Sessions 19+ | F3: Sessions GENERAL INTEREST | I3: Row Labels | J3: Attendance 0-5 | K3: Attendance 6-11 | L3: Attendance 12-18 | M3: Attendance 19+ | N3: Attendance General Interest
A4: 2025 | B4: 262 | C4: 79 | D4: 121 | E4: 266 | F4: 72 | I4: 2025 | J4: 7554 | K4: 1367 | L4: 1426 | M4: 1923 | N4: 3730
A5: Grand Total | B5: 262 | C5: 79 | D5: 121 | E5: 266 | F5: 72 | I5: Grand Total | J5: 7554 | K5: 1367 | L5: 1426 | M5: 1923 | N5: 3730
A11: Month | B11: (Multiple Items) | I11: Month | J11: (Multiple Items)
A13: Row Labels | B13: Sessions 0-5 | C13: Sessions 6-11 | D13: Sessions 12-18 | E13: Sessions 19+ | F13: Sessions GENERAL INTEREST | I13: Row Labels | J13: Attendance 0-5 | K13: Attendance 6-11 | L13: Attendance 12-18 | M13: Attendance 19+ | N13: Attendance General Interest
A14: 2026 | B14: 146 | C14: 48 | D14: 42 | E14: 104 | F14: 15 | I14: 2026 | J14: 4324 | K14: 562 | L14: 349 | M14: 766 | N14: 659
A15: Grand Total | B15: 146 | C15: 48 | D15: 42 | E15: 104 | F15: 15 | I15: Grand Total | J15: 4324 | K15: 562 | L15: 349 | M15: 766 | N15: 659
A18: Fiscal Year | I18: Fiscal Year
A19: 25-26 Totals | I19: 25-26 Totals
A20: 25-26 | B20: Sessions 0-5 | C20: Sessions 6-11 | D20: Sessions 12-18 | E20: Sessions 19+ | F20: Sessions GENERAL INTEREST | J20: Attendance 0-5 | K20: Attendance 6-11 | L20: Attendance 12-18 | M20: Attendance 19+ | N20: Attendance General Interest
B21: =SUM(GETPIVOTDATA("Sessions 0-5",$A$3,"Year",2025)+GETPIVOTDATA("Sessions 0-5",$A$13,"Year",2026)) -> 408 | C21: =SUM(GETPIVOTDATA("Sessions 6-11",$A$3,"Year",2025)+GETPIVOTDATA("Sessions 6-11",$A$13,"Year",2026)) -> 127 | D21: =SUM(GETPIVOTDATA("Sessions 12-18",$A$3,"Year",2025)+GETPIVOTDATA("Sessions 12-18",$A$13,"Year",2026)) -> 163 | E21: =SUM(GETPIVOTDATA("Sessions 19+",$A$3,"Year",2025)+GETPIVOTDATA("Sessions 19+",$A$13,"Year",2026)) -> 370 | F21: =SUM(GETPIVOTDATA("Sessions GENERAL INTEREST",$A$3,"Year",2025)+GETPIVOTDATA("Sessions GENERAL INTEREST",$A$13,"Year",2026)) -> 87 | I21: 25-26 | J21: =SUM(GETPIVOTDATA("Attendance 0-5",$I$3,"Year",2025)+GETPIVOTDATA("Attendance 0-5",$I$13,"Year",2026)) -> 11878 | K21: =SUM(GETPIVOTDATA("Attendance 6-11",$I$3,"Year",2025)+GETPIVOTDATA("Attendance 6-11",$I$13,"Year",2026)) -> 1929 | L21: =SUM(GETPIVOTDATA("Attendance 12-18",$I$3,"Year",2025)+GETPIVOTDATA("Attendance 12-18",$I$13,"Year",2026)) -> 1775 | M21: =SUM(GETPIVOTDATA("Attendance 19+",$I$13,"Year",2026)+GETPIVOTDATA("Attendance 19+",$I$3,"Year",2025)) -> 2689 | N21: =SUM(GETPIVOTDATA("Attendance General Interest",$I$3,"Year",2025)+GETPIVOTDATA("Attendance General Interest",$I$13,"Year",2026)) -> 4389
I23: Annual Toral | J23: =SUM(J21:N21) -> 22660
A24: Annual Total | B24: =SUM(B21:F21) -> 1155

Sheet Online use
A1: Month | B1: March | H1: Month | I1: (Multiple Items) | M1: Month | N1: (Multiple Items)
H2: Year | I2: 2025 | M2: Year | N2: 2026
A3: Row Labels | B3: Website Hits | C3: Contact Us | D3: YCLApp Users | E3: YCLApp Sessions
A4: 2025 | B4: 26431 | C4: 53 | D4: 1262 | E4: 5287 | H4: Website Hits | I4: Contact Us | J4: YCLApp Users | K4: YCLApp Sessions | M4: Website Hits | N4: Contact Us | O4: YCLApp Users | P4: YCLApp Sessions
A5: 2026 | B5: 28476 | C5: 39 | D5: 2319 | E5: 46299 | H5: 183822 | I5: 312 | J5: 13378 | K5: 67571 | M5: 85083 | N5: 112 | O5: 6479 | P5: 106581
A6: Grand Total | B6: 54907 | C6: 92 | D6: 3581 | E6: 51586
H11: Fiscal Year
H12: 25-26 Totals
H13: Website Hits | I13: Contact Us | J13: YCLApp Users | K13: YCLApp Sessions
H14: =SUM(GETPIVOTDATA("Website Hits",$H$4)+GETPIVOTDATA("Website Hits",$M$4)) -> 268905 | I14: =SUM(GETPIVOTDATA("Contact Us",$H$4)+GETPIVOTDATA("Contact Us",$M$4)) -> 424 | J14: =SUM(GETPIVOTDATA("YCLApp Users",$H$4)+GETPIVOTDATA("YCLApp Users",$M$4)) -> 19857 | K14: =SUM(GETPIVOTDATA("YCLApp Sessions",$H$4)+GETPIVOTDATA("YCLApp Sessions",$M$4)) -> 174152

Sheet Outreach etc
A1: Month | B1: 04-April
A2: BRANCH | B2: (Multiple Items)
A4: Row Labels | B4: Sum of I22: TOTAL # TAKE & MAKES and OTHER PASSIVE PROGRAM PARTICIPANTS | C4: Sum of Outreach Attendance (YCL Internal) | D4: Sum of I21: NUMBER OF OUTREACH ACTIVITIES Conducted
A5: 2024 | B5: 849
A6: 2025 | B6: 29
A7: Grand Total | B7: 878
A11: Month | B11: 04-April
A12: BRANCH | B12: (Multiple Items)
A14: Row Labels | B14: Sum of I21: NUMBER OF OUTREACH ACTIVITIES Conducted | C14: Sum of Outreach Attendance (YCL Internal) | D14: Sum of I22: TOTAL # TAKE & MAKES and OTHER PASSIVE PROGRAM PARTICIPANTS | E14: Sum of I23: NUMBER OF STAFF TAKING TRAINING | F14: Sum of I24: NUMBER OF HOURS STAFF ATTENDED TRAINING
A15: 2024 | D15: 385 | E15: 2 | F15: 8
A16: 2025 | D16: 21 | E16: 2 | F16: 8
A17: Grand Total | D17: 406 | E17: 4 | F17: 16

Sheet Social
A1: Month | B1: March | J1: Month | K1: (Multiple Items) | M1: Month | N1: (Multiple Items)
J2: Year | K2: 2025 | M2: Year | N2: 2026
A3: Row Labels | B3: Instragram - Subscriptions | C3: Facebook - Followers
A4: 2025 | B4: 22642 | C4: 8619 | J4: Instragram - Subscriptions | K4: Facebook - Followers | M4: Instragram - Subscriptions | N4: Facebook - Followers
A5: 2026 | B5: 2345 | C5: 9785 | J5: 15221 | K5: 64945 | M5: 6931 | N5: 29033
A6: Grand Total | B6: 24987 | C6: 18404
J10: Fisal Year
A11: Month | B11: March | J11: 25-26 Totals
J12: Instragram - Subscriptions | K12: Facebook - Followers
A13: Row Labels | B13: YouTube -- Views | C13: Youtube -- Subscribers | J13: =SUM(GETPIVOTDATA("Instragram - Subscriptions",$J$4)+GETPIVOTDATA("Instragram - Subscriptions",$M$4)) -> 22152 | K13: =SUM(GETPIVOTDATA("Facebook - Followers",$J$4)+GETPIVOTDATA("Facebook - Followers",$M$4)) -> 93978
A14: 2025 | B14: 3525 | C14: 1200
A15: 2026 | B15: 1751 | C15: 1280
A16: Grand Total | B16: 5276 | C16: 2480

Sheet Tech Use
A1: Month | B1: March | G1: Month | H1: (Multiple Items) | L1: Month | M1: (Multiple Items)
G2: Year | H2: 2025 | L2: Year | M2: 2026
A3: Row Labels | B3: Monthly PC Reservations | C3: WiFi -- Unique Sessions | D3: Hotspots - Circulation | E3: Monthly Total Prints
A4: 2025 | B4: 3819 | C4: 7606 | D4: 380 | E4: 1699 | G4: Monthly PC Reservations | H4: WiFi -- Unique Sessions | I4: Hotspots - Circulation | J4: Monthly Total Prints | L4: Monthly PC Reservations | M4: WiFi -- Unique Sessions | N4: Hotspots - Circulation | O4: Monthly Total Prints
A5: 2026 | B5: 1953 | C5: 3858 | D5: 288 | E5: 7508 | G5: 14134 | H5: 32176 | I5: 1677 | J5: 30137 | L5: 5269 | M5: 10654 | N5: 810 | O5: 16136
A6: Grand Total | B6: 5772 | C6: 11464 | D6: 668 | E6: 9207
G8: Fiscal Year
G9: 25-26 Totals
G10: Monthly PC Reservations | H10: WiFi -- Unique Sessions | I10: Hotspots - Circulation | J10: Monthly Total Prints
G11: =SUM(GETPIVOTDATA("Monthly PC Reservations",$G$4)+GETPIVOTDATA("Monthly PC Reservations",$L$4)) -> 19403 | H11: =SUM(GETPIVOTDATA("WiFi -- Unique Sessions",$G$4)+GETPIVOTDATA("WiFi -- Unique Sessions",$L$4)) -> 42830 | I11: =SUM(GETPIVOTDATA("Hotspots - Circulation",$G$4)+GETPIVOTDATA("Hotspots - Circulation",$L$4)) -> 2487 | J11: =SUM(GETPIVOTDATA("Monthly Total Prints",$G$4)+GETPIVOTDATA("Monthly Total Prints",$L$4)) -> 46273

Sheet Hotspots
A1: Month | B1: (Multiple Items) | D1: Month | E1: (Multiple Items)
A3: Row Labels | B3: Total Hotspots Circulation | D3: Row Labels | E3: Total Hotspots Circulation
A4: 2024 | B4: 1990 | D4: 2025 | E4: 2171
A5: Grand Total | B5: 1990 | D5: Grand Total | E5: 2171
A8: Fiscal Year
A9: 25-26 Totals
A10: Hotspot Circulcation
A11: =SUM(GETPIVOTDATA("Hotspots Circulation",$A$3,"Year",2024)+GETPIVOTDATA("Hotspots Circulation",$D$3,"Year",2025)) -> 4161

Sheet Training
A2: Month | B2: 04-April
A4: Row Labels | B4: Sum of I23: NUMBER OF STAFF TAKING TRAINING | C4: Sum of I24: NUMBER OF HOURS STAFF ATTENDED TRAINING
A5: 2024 | B5: 27 | C5: 109
A6: 2025 | B6: 29 | C6: 128
A7: Grand Total | B7: 56 | C7: 237

Sheet Branch Stats
A1: Month Num | B1: Month | C1: BRANCH | D1: New Library Card Registrations, Adult (includes YA) | E1: New Library Card Registrations, Juvenile | F1: Gate Count | G1: PC Reservations | H1: WiFi - Unique Sessions | I1: External Party Library Room Use | J1: Total Branch Circulation | K1: Hotspots Circulation | L1: Curbside | M1: ILL - Sent (Main ONLY) | N1: ILL - Received (Main ONLY) | O1: ICLs - Sent (MAIN ONLY) | P1: ICLs - Received (MAIN ONLY) | Q1: Total Prints per Month | R1: I2: ONSITE Sessions 0-5 | S1: I3: ONSITE Sessions 6-11 | T1: I4: ONSITE Sessions 12-18 | U1: I5: ONSITE Sessions 19+ | V1: I6: ONSITE Sessions GENERAL INTEREST | W1: ONSITE Attendance 0-5 | X1: ONSITE Attendance 6-11 | Y1: ONSITE Attendance 12-18 | Z1: ONSITE Attendance 19+ | AA1: ONSITE Attendance General Interest | AB1: OFFSITE Sessions 0-5 | AC1: OFFSITE Sessions 6-11 | AD1: OFFSITE Sessions 12-18 | AE1: OFFSITE Sessions 19+ | AF1: OFFSITE Sessions General Interest | AG1: OFFSITE Attendance 0-5 | AH1: OFFSITE Attendance 6-11 | AI1: OFFSITE Attendance 12-18 | AJ1: OFFSITE Attendance 19+ | AK1: OFFSITE Attendance General Interest | AL1: VIRTUAL Sessions 0-5 | AM1: VIRTUAL Sessions 6-11 | AN1: VIRTUAL Sessions 12-18 | AO1: VIRTUAL Sessions 19+ | AP1: VIRTUAL Sessions General Interest | AQ1: VIRTUAL Attendance 0-5 | AR1: VIRTUAL Attendance 6-11 | AS1: VIRTUAL Attendance 12-18 | AT1: VIRTUAL Attendance 19+ | AU1: VIRTUAL Attendance General Interest | AV1: I21: NUMBER OF OUTREACH ACTIVITIES Conducted | AW1: Outreach Attendance (YCL Internal) | AX1: I22: TOTAL # TAKE & MAKES and OTHER PASSIVE PROGRAM PARTICIPANTS | AY1: I23: NUMBER OF STAFF TAKING TRAINING | AZ1: I24: NUMBER OF HOURS STAFF ATTENDED TRAINING | BA1: 1-on-1 Total for Month | BB1: Email Address | BC1: Year | BD1: Locker Circulation
A2: 1 | B2: January | C2: ROCK HILL | E2: 237 | F2: 13105 | J2: 14481 | K2: 121 | M2: 7 | N2: 105 | BC2: 2024
A3: 1 | B3: January | C3: CLOVER | E3: 43 | F3: 2152 | G3: 216 | I3: 1 | J3: 2594 | K3: 67 | R3: 10 | S3: 2 | T3: 2 | U3: 4 | V3: 2 | W3: 119 | X3: 25 | Y3: 11 | Z3: 27 | AA3: 75 | AX3: 30 | AY3: 38 | AZ3: 26.5 | BC3: 2024
A4: 1 | B4: January | C4: FORT MILL | E4: 281 | F4: 10005 | G4: 679 | I4: 6 | J4: 18615 | K4: 33 | L4: 5 | R4: 30 | S4: 5 | T4: 5 | U4: 10 | V4: 4 | W4: 867 | X4: 63 | Y4: 47 | Z4: 85 | AA4: 184 | AX4: 469 | BC4: 2024
A5: 1 | B5: January | C5: LAKE WYLIE | E5: 75 | F5: 3147 | G5: 138 | I5: 9 | J5: 4442 | K5: 12 | L5: 3 | R5: 1 | S5: 2 | T5: 2 | U5: 10 | V5: 0 | W5: 8 | X5: 6 | Y5: 4 | Z5: 105 | AA5: 0 | AC5: 0 | AH5: 0 | AX5: 261 | AY5: 1 | AZ5: 9 | BA5: 2 | BC5: 2024
A6: 1 | B6: January | C6: YORK | E6: 54 | F6: 3430 | G6: 395 | I6: 3 | J6: 3551 | K6: 99 | L6: 0 | R6: 10 | S6: 2 | T6: 2 | U6: 9 | W6: 146 | X6: 56 | Y6: 15 | Z6: 91 | AX6: 150 | AY6: 4 | AZ6: 16 | BA6: 3 | BC6: 2024
A7: 1 | B7: January | C7: OUTREACH/BOOKMOBILE | E7: 18 | F7: 625 | J7: 1342 | K7: 0 | R7: 3 | W7: 96 | AX7: 130 | AY7: 1 | AZ7: 1 | BC7: 2024
A8: 1 | B8: January | C8: YCL (System Wide) | H8: 0 | Q8: 4548 | BC8: 2024
A9: 2 | B9: February | C9: ROCK HILL | E9: 205 | F9: 13867 | J9: 14107 | K9: 121 | BC9: 2024
A10: 2 | B10: February | C10: CLOVER | E10: 31 | F10: 2241 | G10: 207 | J10: 2693 | K10: 57 | R10: 13 | S10: 1 | T10: 1 | U10: 7 | V10: 2 | W10: 170 | X10: 10 | Y10: 5 | Z10: 56 | AA10: 46 | AX10: 0 | AY10: 35 | AZ10: 59.5 | BC10: 2024
A11: 2 | B11: February | C11: FORT MILL | E11: 223 | F11: 11408 | G11: 686 | I11: 14 | J11: 17829 | K11: 32 | L11: 6 | R11: 23 | S11: 6 | T11: 7 | U11: 14 | V11: 4 | W11: 683 | X11: 66 | Y11: 93 | Z11: 116 | AA11: 154 | AC11: 1 | AH11: 400 | AX11: 365 | AY11: 16 | AZ11: 120 | BC11: 2024
A12: 2 | B12: February | C12: LAKE WYLIE | E12: 61 | F12: 3400 | G12: 193 | I12: 11 | J12: 4250 | K12: 12 | L12: 3 | R12: 5 | S12: 4 | T12: 2 | U12: 13 | V12: 0 | W12: 52 | X12: 47 | Y12: 8 | Z12: 118 | AA12: 0 | AC12: 0 | AH12: 0 | AX12: 432 | AY12: 1 | AZ12: 86 | BA12: 5 | BC12: 2024
A13: 2 | B13: February | C13: YORK | E13: 59 | F13: 3286 | G13: 409 | I13: 5 | J13: 3430 | K13: 81 | L13: 0 | R13: 7 | S13: 3 | T13: 1 | U13: 8 | V13: 1 | W13: 73 | X13: 68 | Y13: 5 | Z13: 67 | AA13: 20 | AC13: 1 | AH13: 57 | AX13: 48 | AY13: 18 | AZ13: 86.5 | BA13: 2 | BC13: 2024
A14: 2 | B14: February | C14: OUTREACH/BOOKMOBILE | E14: 36 | F14: 1153 | J14: 1764 | K14: 3 | R14: 4 | W14: 104 | AY14: 1 | AZ14: 1.5 | BC14: 2024
A15: 2 | B15: February | C15: YCL (System Wide) | H15: 0 | L15: 21 | Q15: 5467 | BC15: 2024
A16: 3 | B16: March | C16: ROCK HILL | E16: 217 | F16: 15534 | G16: 2125 | I16: 6 | J16: 17206 | K16: 141 | M16: 6 | N16: 131 | R16: 31 | S16: 5 | T16: 13 | U16: 27 | V16: 6 | W16: 1188 | X16: 116 | Y16: 155 | Z16: 277 | AA16: 106 | AC16: 7 | AH16: 111 | AX16: 30 | AY16: 42 | AZ16: 40.5 | BA16: 10 | BC16: 2024
A17: 3 | B17: March | C17: CLOVER | E17: 39 | F17: 2402 | G17: 208 | I17: 0 | J17: 2858 | K17: 62 | R17: 7 | S17: 2 | T17: 2 | U17: 6 | V17: 1 | W17: 62 | X17: 14 | Y17: 11 | Z17: 48 | AA17: 10 | AX17: 20 | AY17: 19 | AZ17: 20 | BA17: 0 | BC17: 2024
A18: 3 | B18: March | C18: FORT MILL | E18: 201 | F18: 12508 | G18: 810 | I18: 14 | J18: 19038 | K18: 23 | L18: 5 | R18: 33 | S18: 6 | T18: 7 | U18: 14 | V18: 4 | W18: 1059 | X18: 88 | Y18: 75 | Z18: 128 | AA18: 145 | AX18: 320 | AY18: 5 | AZ18: 5 | BC18: 2024
A19: 3 | B19: March | C19: LAKE WYLIE | E19: 67 | F19: 3808 | G19: 218 | I19: 12 | J19: 4857 | K19: 8 | L19: 2 | R19: 4 | S19: 2 | T19: 2 | U19: 13 | V19: 2 | W19: 39 | X19: 7 | Y19: 19 | Z19: 122 | AA19: 16 | AC19: 0 | AH19: 0 | AX19: 365 | AY19: 1 | AZ19: 53 | BA19: 9 | BC19: 2024
A20: 3 | B20: March | C20: YORK | E20: 49 | F20: 3798 | G20: 458 | I20: 4 | J20: 3862 | K20: 91 | L20: 0 | R20: 14 | S20: 1 | T20: 1 | U20: 8 | W20: 162 | X20: 4 | Y20: 4 | Z20: 61 | AC20: 1 | AH20: 20 | AX20: 45 | AY20: 11 | AZ20: 66 | BA20: 0 | BC20: 2024
A21: 3 | B21: March | C21: OUTREACH/BOOKMOBILE | E21: 33 | F21: 507 | J21: 1184 | K21: 1 | R21: 4 | W21: 123 | AX21: 489 | AY21: 2 | AZ21: 2 | BA21: 3 | BC21: 2024
A22: 3 | B22: March | C22: YCL (System Wide) | H22: 0 | Q22: 6478 | BC22: 2024
A23: 4 | B23: April | C23: ROCK HILL | E23: 204 | F23: 15313 | G23: 2034 | I23: 4 | J23: 15145 | K23: 132 | L23: 27 | M23: 6 | N23: 116 | R23: 22 | S23: 6 | T23: 15 | U23: 29 | V23: 6 | W23: 890 | X23: 277 | Y23: 162 | Z23: 292 | AA23: 156 | AC23: 6 | AH23: 60 | AX23: 50 | AY23: 14 | AZ23: 21.5 | BA23: 8 | BC23: 2024
A24: 4 | B24: April | C24: CLOVER | E24: 85 | F24: 2761 | G24: 214 | I24: 1 | J24: 3132 | K24: 63 | L24: 0 | R24: 8 | S24: 2 | T24: 2 | U24: 1 | V24: 3 | W24: 85 | X24: 21 | Y24: 6 | Z24: 4 | AA24: 30 | AC24: 0 | AH24: 0 | AX24: 20 | AY24: 4 | AZ24: 25 | BA24: 0 | BC24: 2024
A25: 4 | B25: April | C25: FORT MILL | E25: 215 | F25: 11737 | G25: 781 | I25: 6 | J25: 19642 | K25: 26 | L25: 5 | R25: 21 | S25: 9 | T25: 7 | U25: 11 | V25: 6 | W25: 754 | X25: 778 | Y25: 65 | Z25: 94 | AA25: 265 | AC25: 3 | AH25: 800 | AX25: 402 | AY25: 2 | AZ25: 2 | BC25: 2024
A26: 4 | B26: April | C26: LAKE WYLIE | E26: 63 | F26: 3866 | G26: 188 | I26: 10 | J26: 4663 | K26: 11 | L26: 2 | R26: 4 | S26: 4 | T26: 2 | U26: 12 | V26: 2 | W26: 40 | X26: 20 | Y26: 9 | Z26: 100 | AA26: 11 | AC26: 0 | AH26: 0 | AX26: 372 | AY26: 1 | AZ26: 24.5 | BA26: 5 | BC26: 2024
A27: 4 | B27: April | C27: YORK | E27: 50 | F27: 3598 | G27: 377 | I27: 2 | J27: 3804 | K27: 103 | L27: 0 | R27: 12 | S27: 3 | T27: 1 | U27: 7 | W27: 206 | X27: 66 | Y27: 4 | Z27: 61 | AC27: 1 | AH27: 150 | AX27: 5 | AY27: 4 | AZ27: 28 | BA27: 0 | BC27: 2024
A28: 4 | B28: April | C28: OUTREACH/BOOKMOBILE | E28: 8 | F28: 905 | J28: 1647 | K28: 3 | R28: 1 | U28: 2 | W28: 25 | Z28: 16 | AX28: 385 | AY28: 2 | AZ28: 8 | BC28: 2024
A29: 4 | B29: April | C29: YCL (System Wide) | H29: 0 | Q29: 5306 | BC29: 2024
A30: 5 | B30: May | C30: ROCK HILL | E30: 209 | F30: 17040 | G30: 1972 | I30: 12 | J30: 19243 | K30: 139 | L30: 38 | M30: 4 | N30: 122 | R30: 15 | S30: 6 | T30: 10 | U30: 22 | V30: 8 | W30: 636 | X30: 140 | Y30: 59 | Z30: 245 | AA30: 1644 | AC30: 5 | AH30: 21 | AX30: 0 | AY30: 15 | AZ30: 14.5 | BA30: 7 | BC30: 2024
A31: 5 | B31: May | C31: CLOVER | E31: 32 | F31: 2618 | G31: 229 | I31: 1 | J31: 3426 | K31: 60 | L31: 0 | R31: 10 | S31: 2 | T31: 3 | U31: 3 | V31: 0 | W31: 155 | X31: 12 | Y31: 17 | Z31: 28 | AA31: 0 | AC31: 0 | AH31: 0 | AX31: 0 | AY31: 1 | AZ31: 25 | BA31: 0 | BC31: 2024
A32: 5 | B32: May | C32: FORT MILL | E32: 228 | F32: 12340 | G32: 747 | I32: 4 | J32: 20990 | K32: 28 | L32: 5 | R32: 21 | S32: 5 | T32: 5 | U32: 10 | V32: 5 | W32: 714 | X32: 70 | Y32: 84 | Z32: 96 | AA32: 894 | AC32: 1 | AH32: 770 | AX32: 504 | AY32: 2 | AZ32: 2 | BC32: 2024
A33: 5 | B33: May | C33: LAKE WYLIE | E33: 55 | F33: 3939 | G33: 163 | I33: 4 | J33: 5447 | K33: 9 | L33: 2 | R33: 4 | S33: 5 | T33: 2 | U33: 9 | V33: 3 | W33: 50 | X33: 51 | Y33: 11 | Z33: 91 | AA33: 3 | AC33: 0 | AH33: 0 | AX33: 411 | AY33: 1 | AZ33: 9 | BA33: 1 | BC33: 2024
A34: 5 | B34: May | C34: YORK | E34: 72 | F34: 3958 | G34: 451 | I34: 2 | J34: 4424 | K34: 98 | L34: 0 | R34: 10 | S34: 3 | T34: 7 | U34: 9 | V34: 1 | W34: 135 | X34: 72 | Y34: 7 | Z34: 69 | AA34: 112 | AX34: 0 | AY34: 3 | AZ34: 9 | BA34: 0 | BC34: 2024
A35: 5 | B35: May | C35: OUTREACH/BOOKMOBILE | E35: 12 | F35: 571 | J35: 1324 | K35: 1 | R35: 1 | W35: 8 | AX35: 133 | BC35: 2024
A36: 5 | B36: May | C36: YCL (System Wide) | H36: 0 | Q36: 6526 | BC36: 2024
A37: 6 | B37: June | C37: ROCK HILL | E37: 325 | F37: 17538 | G37: 1922 | H37: 3497 | I37: 3 | J37: 21648 | K37: 122 | M37: 122 | N37: 4 | O37: 2857 | P37: 6142 | R37: 11 | S37: 4 | T37: 18 | U37: 19 | V37: 16 | W37: 456 | X37: 88 | Y37: 237 | Z37: 164 | AA37: 1609 | AY37: 15 | AZ37: 14 | BA37: 18 | BC37: 2024 | BD37: 159
A38: 6 | B38: June | C38: CLOVER | E38: 50 | F38: 3142 | G38: 323 | H38: 505 | I38: 1 | J38: 4678 | K38: 57 | O38: 992 | P38: 1832 | R38: 11 | S38: 3 | T38: 2 | U38: 6 | V38: 7 | W38: 175 | X38: 47 | Y38: 17 | Z38: 46 | AA38: 260 | AY38: 28 | AZ38: 31 | BA38: 0 | BC38: 2024 | BD38: 43
A39: 6 | B39: June | C39: FORT MILL | E39: 329 | F39: 12647 | G39: 913 | H39: 1944 | I39: 0 | J39: 23998 | K39: 28 | O39: 1523 | P39: 6441 | R39: 22 | S39: 4 | T39: 7 | U39: 8 | V39: 17 | W39: 684 | X39: 113 | Y39: 71 | Z39: 76 | AA39: 998 | AY39: 0 | AZ39: 0 | BA39: 0 | BC39: 2024 | BD39: 241
A40: 6 | B40: June | C40: LAKE WYLIE | E40: 91 | F40: 4927 | G40: 202 | H40: 665 | I40: 6 | J40: 6109 | K40: 18 | O40: 1337 | P40: 2787 | R40: 6 | S40: 3 | T40: 3 | U40: 9 | V40: 1 | W40: 138 | X40: 32 | Y40: 31 | Z40: 71 | AA40: 72 | AY40: 1 | AZ40: 20 | BA40: 5 | BC40: 2024 | BD40: 128
...

Sheet eResources
